Workbook

Sheet Results
C16: Test | D16: Time | E16: Date | F16: Cassette Identifier Code | G16: Sample ID | H16: Result | I16: Method | J16: Version | K16: Lot Code | L16: View
C17: 1 | D17: =IF(ISBLANK('Raw Data'!C$1),"",'Raw Data'!C$1) | E17: =IF(ISBLANK('Raw Data'!C$2),"",'Raw Data'!C$2) | F17: =IF(ISBLANK('Raw Data'!C$3),"",'Raw Data'!C$3) | G17: =IF(ISBLANK('Raw Data'!C$4),"",'Raw Data'!C$4) | H17: =IF(ISBLANK('Raw Data'!C$5),"",'Raw Data'!C$5) | I17: =IF(ISBLANK('Raw Data'!C$6),"",'Raw Data'!C$6) | J17: =IF(ISBLANK('Raw Data'!C$7),"",'Raw Data'!C$7) | K17: =IF(ISBLANK('Raw Data'!C$8),"",'Raw Data'!C$8) | L17: TRUE
C18: 2 | D18: =IF(ISBLANK('Raw Data'!D$1),"",'Raw Data'!D$1) | E18: =IF(ISBLANK('Raw Data'!D$2),"",'Raw Data'!D$2) | F18: =IF(ISBLANK('Raw Data'!D$3),"",'Raw Data'!D$3) | G18: =IF(ISBLANK('Raw Data'!D$4),"",'Raw Data'!D$4) | H18: =IF(ISBLANK('Raw Data'!D$5),"",'Raw Data'!D$5) | I18: =IF(ISBLANK('Raw Data'!D$6),"",'Raw Data'!D$6) | J18: =IF(ISBLANK('Raw Data'!D$7),"",'Raw Data'!D$7) | K18: =IF(ISBLANK('Raw Data'!D$8),"",'Raw Data'!D$8) | L18: TRUE
C19: 3 | D19: =IF(ISBLANK('Raw Data'!E$1),"",'Raw Data'!E$1) | E19: =IF(ISBLANK('Raw Data'!E$2),"",'Raw Data'!E$2) | F19: =IF(ISBLANK('Raw Data'!E$3),"",'Raw Data'!E$3) | G19: =IF(ISBLANK('Raw Data'!E$4),"",'Raw Data'!E$4) | H19: =IF(ISBLANK('Raw Data'!E$5),"",'Raw Data'!E$5) | I19: =IF(ISBLANK('Raw Data'!E$6),"",'Raw Data'!E$6) | J19: =IF(ISBLANK('Raw Data'!E$7),"",'Raw Data'!E$7) | K19: =IF(ISBLANK('Raw Data'!E$8),"",'Raw Data'!E$8) | L19: FALSE
C20: 4 | D20: =IF(ISBLANK('Raw Data'!F$1),"",'Raw Data'!F$1) | E20: =IF(ISBLANK('Raw Data'!F$2),"",'Raw Data'!F$2) | F20: =IF(ISBLANK('Raw Data'!F$3),"",'Raw Data'!F$3) | G20: =IF(ISBLANK('Raw Data'!F$4),"",'Raw Data'!F$4) | H20: =IF(ISBLANK('Raw Data'!F$5),"",'Raw Data'!F$5) | I20: =IF(ISBLANK('Raw Data'!F$6),"",'Raw Data'!F$6) | J20: =IF(ISBLANK('Raw Data'!F$7),"",'Raw Data'!F$7) | K20: =IF(ISBLANK('Raw Data'!F$8),"",'Raw Data'!F$8) | L20: FALSE
C21: 5 | D21: =IF(ISBLANK('Raw Data'!G$1),"",'Raw Data'!G$1) | E21: =IF(ISBLANK('Raw Data'!G$2),"",'Raw Data'!G$2) | F21: =IF(ISBLANK('Raw Data'!G$3),"",'Raw Data'!G$3) | G21: =IF(ISBLANK('Raw Data'!G$4),"",'Raw Data'!G$4) | H21: =IF(ISBLANK('Raw Data'!G$5),"",'Raw Data'!G$5) | I21: =IF(ISBLANK('Raw Data'!G$6),"",'Raw Data'!G$6) | J21: =IF(ISBLANK('Raw Data'!G$7),"",'Raw Data'!G$7) | K21: =IF(ISBLANK('Raw Data'!G$8),"",'Raw Data'!G$8) | L21: FALSE
C22: 6 | D22: =IF(ISBLANK('Raw Data'!H$1),"",'Raw Data'!H$1) | E22: =IF(ISBLANK('Raw Data'!H$2),"",'Raw Data'!H$2) | F22: =IF(ISBLANK('Raw Data'!H$3),"",'Raw Data'!H$3) | G22: =IF(ISBLANK('Raw Data'!H$4),"",'Raw Data'!H$4) | H22: =IF(ISBLANK('Raw Data'!H$5),"",'Raw Data'!H$5) | I22: =IF(ISBLANK('Raw Data'!H$6),"",'Raw Data'!H$6) | J22: =IF(ISBLANK('Raw Data'!H$7),"",'Raw Data'!H$7) | K22: =IF(ISBLANK('Raw Data'!H$8),"",'Raw Data'!H$8) | L22: FALSE
C23: 7 | D23: =IF(ISBLANK('Raw Data'!I$1),"",'Raw Data'!I$1) | E23: =IF(ISBLANK('Raw Data'!I$2),"",'Raw Data'!I$2) | F23: =IF(ISBLANK('Raw Data'!I$3),"",'Raw Data'!I$3) | G23: =IF(ISBLANK('Raw Data'!I$4),"",'Raw Data'!I$4) | H23: =IF(ISBLANK('Raw Data'!I$5),"",'Raw Data'!I$5) | I23: =IF(ISBLANK('Raw Data'!I$6),"",'Raw Data'!I$6) | J23: =IF(ISBLANK('Raw Data'!I$7),"",'Raw Data'!I$7) | K23: =IF(ISBLANK('Raw Data'!I$8),"",'Raw Data'!I$8) | L23: FALSE
C24: 8 | D24: =IF(ISBLANK('Raw Data'!J$1),"",'Raw Data'!J$1) | E24: =IF(ISBLANK('Raw Data'!J$2),"",'Raw Data'!J$2) | F24: =IF(ISBLANK('Raw Data'!J$3),"",'Raw Data'!J$3) | G24: =IF(ISBLANK('Raw Data'!J$4),"",'Raw Data'!J$4) | H24: =IF(ISBLANK('Raw Data'!J$5),"",'Raw Data'!J$5) | I24: =IF(ISBLANK('Raw Data'!J$6),"",'Raw Data'!J$6) | J24: =IF(ISBLANK('Raw Data'!J$7),"",'Raw Data'!J$7) | K24: =IF(ISBLANK('Raw Data'!J$8),"",'Raw Data'!J$8) | L24: FALSE
C25: 9 | D25: =IF(ISBLANK('Raw Data'!K$1),"",'Raw Data'!K$1) | E25: =IF(ISBLANK('Raw Data'!K$2),"",'Raw Data'!K$2) | F25: =IF(ISBLANK('Raw Data'!K$3),"",'Raw Data'!K$3) | G25: =IF(ISBLANK('Raw Data'!K$4),"",'Raw Data'!K$4) | H25: =IF(ISBLANK('Raw Data'!K$5),"",'Raw Data'!K$5) | I25: =IF(ISBLANK('Raw Data'!K$6),"",'Raw Data'!K$6) | J25: =IF(ISBLANK('Raw Data'!K$7),"",'Raw Data'!K$7) | K25: =IF(ISBLANK('Raw Data'!K$8),"",'Raw Data'!K$8) | L25: FALSE
C26: 10 | D26: =IF(ISBLANK('Raw Data'!L$1),"",'Raw Data'!L$1) | E26: =IF(ISBLANK('Raw Data'!L$2),"",'Raw Data'!L$2) | F26: =IF(ISBLANK('Raw Data'!L$3),"",'Raw Data'!L$3) | G26: =IF(ISBLANK('Raw Data'!L$4),"",'Raw Data'!L$4) | H26: =IF(ISBLANK('Raw Data'!L$5),"",'Raw Data'!L$5) | I26: =IF(ISBLANK('Raw Data'!L$6),"",'Raw Data'!L$6) | J26: =IF(ISBLANK('Raw Data'!L$7),"",'Raw Data'!L$7) | K26: =IF(ISBLANK('Raw Data'!L$8),"",'Raw Data'!L$8) | L26: FALSE
C27: 11 | D27: =IF(ISBLANK('Raw Data'!M$1),"",'Raw Data'!M$1) | E27: =IF(ISBLANK('Raw Data'!M$2),"",'Raw Data'!M$2) | F27: =IF(ISBLANK('Raw Data'!M$3),"",'Raw Data'!M$3) | G27: =IF(ISBLANK('Raw Data'!M$4),"",'Raw Data'!M$4) | H27: =IF(ISBLANK('Raw Data'!M$5),"",'Raw Data'!M$5) | I27: =IF(ISBLANK('Raw Data'!M$6),"",'Raw Data'!M$6) | J27: =IF(ISBLANK('Raw Data'!M$7),"",'Raw Data'!M$7) | K27: =IF(ISBLANK('Raw Data'!M$8),"",'Raw Data'!M$8) | L27: FALSE
C28: 12 | D28: =IF(ISBLANK('Raw Data'!N$1),"",'Raw Data'!N$1) | E28: =IF(ISBLANK('Raw Data'!N$2),"",'Raw Data'!N$2) | F28: =IF(ISBLANK('Raw Data'!N$3),"",'Raw Data'!N$3) | G28: =IF(ISBLANK('Raw Data'!N$4),"",'Raw Data'!N$4) | H28: =IF(ISBLANK('Raw Data'!N$5),"",'Raw Data'!N$5) | I28: =IF(ISBLANK('Raw Data'!N$6),"",'Raw Data'!N$6) | J28: =IF(ISBLANK('Raw Data'!N$7),"",'Raw Data'!N$7) | K28: =IF(ISBLANK('Raw Data'!N$8),"",'Raw Data'!N$8) | L28: FALSE
C29: 13 | D29: =IF(ISBLANK('Raw Data'!O$1),"",'Raw Data'!O$1) | E29: =IF(ISBLANK('Raw Data'!O$2),"",'Raw Data'!O$2) | F29: =IF(ISBLANK('Raw Data'!O$3),"",'Raw Data'!O$3) | G29: =IF(ISBLANK('Raw Data'!O$4),"",'Raw Data'!O$4) | H29: =IF(ISBLANK('Raw Data'!O$5),"",'Raw Data'!O$5) | I29: =IF(ISBLANK('Raw Data'!O$6),"",'Raw Data'!O$6) | J29: =IF(ISBLANK('Raw Data'!O$7),"",'Raw Data'!O$7) | K29: =IF(ISBLANK('Raw Data'!O$8),"",'Raw Data'!O$8) | L29: FALSE
C30: 14 | D30: =IF(ISBLANK('Raw Data'!P$1),"",'Raw Data'!P$1) | E30: =IF(ISBLANK('Raw Data'!P$2),"",'Raw Data'!P$2) | F30: =IF(ISBLANK('Raw Data'!P$3),"",'Raw Data'!P$3) | G30: =IF(ISBLANK('Raw Data'!P$4),"",'Raw Data'!P$4) | H30: =IF(ISBLANK('Raw Data'!P$5),"",'Raw Data'!P$5) | I30: =IF(ISBLANK('Raw Data'!P$6),"",'Raw Data'!P$6) | J30: =IF(ISBLANK('Raw Data'!P$7),"",'Raw Data'!P$7) | K30: =IF(ISBLANK('Raw Data'!P$8),"",'Raw Data'!P$8) | L30: FALSE
C31: 15 | D31: =IF(ISBLANK('Raw Data'!Q$1),"",'Raw Data'!Q$1) | E31: =IF(ISBLANK('Raw Data'!Q$2),"",'Raw Data'!Q$2) | F31: =IF(ISBLANK('Raw Data'!Q$3),"",'Raw Data'!Q$3) | G31: =IF(ISBLANK('Raw Data'!Q$4),"",'Raw Data'!Q$4) | H31: =IF(ISBLANK('Raw Data'!Q$5),"",'Raw Data'!Q$5) | I31: =IF(ISBLANK('Raw Data'!Q$6),"",'Raw Data'!Q$6) | J31: =IF(ISBLANK('Raw Data'!Q$7),"",'Raw Data'!Q$7) | K31: =IF(ISBLANK('Raw Data'!Q$8),"",'Raw Data'!Q$8) | L31: FALSE
C32: 16 | D32: =IF(ISBLANK('Raw Data'!R$1),"",'Raw Data'!R$1) | E32: =IF(ISBLANK('Raw Data'!R$2),"",'Raw Data'!R$2) | F32: =IF(ISBLANK('Raw Data'!R$3),"",'Raw Data'!R$3) | G32: =IF(ISBLANK('Raw Data'!R$4),"",'Raw Data'!R$4) | H32: =IF(ISBLANK('Raw Data'!R$5),"",'Raw Data'!R$5) | I32: =IF(ISBLANK('Raw Data'!R$6),"",'Raw Data'!R$6) | J32: =IF(ISBLANK('Raw Data'!R$7),"",'Raw Data'!R$7) | K32: =IF(ISBLANK('Raw Data'!R$8),"",'Raw Data'!R$8) | L32: FALSE
C33: 17 | D33: =IF(ISBLANK('Raw Data'!S$1),"",'Raw Data'!S$1) | E33: =IF(ISBLANK('Raw Data'!S$2),"",'Raw Data'!S$2) | F33: =IF(ISBLANK('Raw Data'!S$3),"",'Raw Data'!S$3) | G33: =IF(ISBLANK('Raw Data'!S$4),"",'Raw Data'!S$4) | H33: =IF(ISBLANK('Raw Data'!S$5),"",'Raw Data'!S$5) | I33: =IF(ISBLANK('Raw Data'!S$6),"",'Raw Data'!S$6) | J33: =IF(ISBLANK('Raw Data'!S$7),"",'Raw Data'!S$7) | K33: =IF(ISBLANK('Raw Data'!S$8),"",'Raw Data'!S$8) | L33: FALSE
C34: 18 | D34: =IF(ISBLANK('Raw Data'!T$1),"",'Raw Data'!T$1) | E34: =IF(ISBLANK('Raw Data'!T$2),"",'Raw Data'!T$2) | F34: =IF(ISBLANK('Raw Data'!T$3),"",'Raw Data'!T$3) | G34: =IF(ISBLANK('Raw Data'!T$4),"",'Raw Data'!T$4) | H34: =IF(ISBLANK('Raw Data'!T$5),"",'Raw Data'!T$5) | I34: =IF(ISBLANK('Raw Data'!T$6),"",'Raw Data'!T$6) | J34: =IF(ISBLANK('Raw Data'!T$7),"",'Raw Data'!T$7) | K34: =IF(ISBLANK('Raw Data'!T$8),"",'Raw Data'!T$8) | L34: FALSE
C35: 19 | D35: =IF(ISBLANK('Raw Data'!U$1),"",'Raw Data'!U$1) | E35: =IF(ISBLANK('Raw Data'!U$2),"",'Raw Data'!U$2) | F35: =IF(ISBLANK('Raw Data'!U$3),"",'Raw Data'!U$3) | G35: =IF(ISBLANK('Raw Data'!U$4),"",'Raw Data'!U$4) | H35: =IF(ISBLANK('Raw Data'!U$5),"",'Raw Data'!U$5) | I35: =IF(ISBLANK('Raw Data'!U$6),"",'Raw Data'!U$6) | J35: =IF(ISBLANK('Raw Data'!U$7),"",'Raw Data'!U$7) | K35: =IF(ISBLANK('Raw Data'!U$8),"",'Raw Data'!U$8) | L35: FALSE
C36: 20 | D36: =IF(ISBLANK('Raw Data'!V$1),"",'Raw Data'!V$1) | E36: =IF(ISBLANK('Raw Data'!V$2),"",'Raw Data'!V$2) | F36: =IF(ISBLANK('Raw Data'!V$3),"",'Raw Data'!V$3) | G36: =IF(ISBLANK('Raw Data'!V$4),"",'Raw Data'!V$4) | H36: =IF(ISBLANK('Raw Data'!V$5),"",'Raw Data'!V$5) | I36: =IF(ISBLANK('Raw Data'!V$6),"",'Raw Data'!V$6) | J36: =IF(ISBLANK('Raw Data'!V$7),"",'Raw Data'!V$7) | K36: =IF(ISBLANK('Raw Data'!V$8),"",'Raw Data'!V$8) | L36: FALSE
C37: 21 | D37: =IF(ISBLANK('Raw Data'!W$1),"",'Raw Data'!W$1) | E37: =IF(ISBLANK('Raw Data'!W$2),"",'Raw Data'!W$2) | F37: =IF(ISBLANK('Raw Data'!W$3),"",'Raw Data'!W$3) | G37: =IF(ISBLANK('Raw Data'!W$4),"",'Raw Data'!W$4) | H37: =IF(ISBLANK('Raw Data'!W$5),"",'Raw Data'!W$5) | I37: =IF(ISBLANK('Raw Data'!W$6),"",'Raw Data'!W$6) | J37: =IF(ISBLANK('Raw Data'!W$7),"",'Raw Data'!W$7) | K37: =IF(ISBLANK('Raw Data'!W$8),"",'Raw Data'!W$8) | L37: FALSE
C38: 22 | D38: =IF(ISBLANK('Raw Data'!X$1),"",'Raw Data'!X$1) | E38: =IF(ISBLANK('Raw Data'!X$2),"",'Raw Data'!X$2) | F38: =IF(ISBLANK('Raw Data'!X$3),"",'Raw Data'!X$3) | G38: =IF(ISBLANK('Raw Data'!X$4),"",'Raw Data'!X$4) | H38: =IF(ISBLANK('Raw Data'!X$5),"",'Raw Data'!X$5) | I38: =IF(ISBLANK('Raw Data'!X$6),"",'Raw Data'!X$6) | J38: =IF(ISBLANK('Raw Data'!X$7),"",'Raw Data'!X$7) | K38: =IF(ISBLANK('Raw Data'!X$8),"",'Raw Data'!X$8) | L38: FALSE
C39: 23 | D39: =IF(ISBLANK('Raw Data'!Y$1),"",'Raw Data'!Y$1) | E39: =IF(ISBLANK('Raw Data'!Y$2),"",'Raw Data'!Y$2) | F39: =IF(ISBLANK('Raw Data'!Y$3),"",'Raw Data'!Y$3) | G39: =IF(ISBLANK('Raw Data'!Y$4),"",'Raw Data'!Y$4) | H39: =IF(ISBLANK('Raw Data'!Y$5),"",'Raw Data'!Y$5) | I39: =IF(ISBLANK('Raw Data'!Y$6),"",'Raw Data'!Y$6) | J39: =IF(ISBLANK('Raw Data'!Y$7),"",'Raw Data'!Y$7) | K39: =IF(ISBLANK('Raw Data'!Y$8),"",'Raw Data'!Y$8) | L39: FALSE
C40: 24 | D40: =IF(ISBLANK('Raw Data'!Z$1),"",'Raw Data'!Z$1) | E40: =IF(ISBLANK('Raw Data'!Z$2),"",'Raw Data'!Z$2) | F40: =IF(ISBLANK('Raw Data'!Z$3),"",'Raw Data'!Z$3) | G40: =IF(ISBLANK('Raw Data'!Z$4),"",'Raw Data'!Z$4) | H40: =IF(ISBLANK('Raw Data'!Z$5),"",'Raw Data'!Z$5) | I40: =IF(ISBLANK('Raw Data'!Z$6),"",'Raw Data'!Z$6) | J40: =IF(ISBLANK('Raw Data'!Z$7),"",'Raw Data'!Z$7) | K40: =IF(ISBLANK('Raw Data'!Z$8),"",'Raw Data'!Z$8) | L40: FALSE
C41: 25 | D41: =IF(ISBLANK('Raw Data'!AA$1),"",'Raw Data'!AA$1) | E41: =IF(ISBLANK('Raw Data'!AA$2),"",'Raw Data'!AA$2) | F41: =IF(ISBLANK('Raw Data'!AA$3),"",'Raw Data'!AA$3) | G41: =IF(ISBLANK('Raw Data'!AA$4),"",'Raw Data'!AA$4) | H41: =IF(ISBLANK('Raw Data'!AA$5),"",'Raw Data'!AA$5) | I41: =IF(ISBLANK('Raw Data'!AA$6),"",'Raw Data'!AA$6) | J41: =IF(ISBLANK('Raw Data'!AA$7),"",'Raw Data'!AA$7) | K41: =IF(ISBLANK('Raw Data'!AA$8),"",'Raw Data'!AA$8) | L41: FALSE
C42: 26 | D42: =IF(ISBLANK('Raw Data'!AB$1),"",'Raw Data'!AB$1) | E42: =IF(ISBLANK('Raw Data'!AB$2),"",'Raw Data'!AB$2) | F42: =IF(ISBLANK('Raw Data'!AB$3),"",'Raw Data'!AB$3) | G42: =IF(ISBLANK('Raw Data'!AB$4),"",'Raw Data'!AB$4) | H42: =IF(ISBLANK('Raw Data'!AB$5),"",'Raw Data'!AB$5) | I42: =IF(ISBLANK('Raw Data'!AB$6),"",'Raw Data'!AB$6) | J42: =IF(ISBLANK('Raw Data'!AB$7),"",'Raw Data'!AB$7) | K42: =IF(ISBLANK('Raw Data'!AB$8),"",'Raw Data'!AB$8) | L42: FALSE
C43: 27 | D43: =IF(ISBLANK('Raw Data'!AC$1),"",'Raw Data'!AC$1) | E43: =IF(ISBLANK('Raw Data'!AC$2),"",'Raw Data'!AC$2) | F43: =IF(ISBLANK('Raw Data'!AC$3),"",'Raw Data'!AC$3) | G43: =IF(ISBLANK('Raw Data'!AC$4),"",'Raw Data'!AC$4) | H43: =IF(ISBLANK('Raw Data'!AC$5),"",'Raw Data'!AC$5) | I43: =IF(ISBLANK('Raw Data'!AC$6),"",'Raw Data'!AC$6) | J43: =IF(ISBLANK('Raw Data'!AC$7),"",'Raw Data'!AC$7) | K43: =IF(ISBLANK('Raw Data'!AC$8),"",'Raw Data'!AC$8) | L43: FALSE
C44: 28 | D44: =IF(ISBLANK('Raw Data'!AD$1),"",'Raw Data'!AD$1) | E44: =IF(ISBLANK('Raw Data'!AD$2),"",'Raw Data'!AD$2) | F44: =IF(ISBLANK('Raw Data'!AD$3),"",'Raw Data'!AD$3) | G44: =IF(ISBLANK('Raw Data'!AD$4),"",'Raw Data'!AD$4) | H44: =IF(ISBLANK('Raw Data'!AD$5),"",'Raw Data'!AD$5) | I44: =IF(ISBLANK('Raw Data'!AD$6),"",'Raw Data'!AD$6) | J44: =IF(ISBLANK('Raw Data'!AD$7),"",'Raw Data'!AD$7) | K44: =IF(ISBLANK('Raw Data'!AD$8),"",'Raw Data'!AD$8) | L44: FALSE
C45: 29 | D45: =IF(ISBLANK('Raw Data'!AE$1),"",'Raw Data'!AE$1) | E45: =IF(ISBLANK('Raw Data'!AE$2),"",'Raw Data'!AE$2) | F45: =IF(ISBLANK('Raw Data'!AE$3),"",'Raw Data'!AE$3) | G45: =IF(ISBLANK('Raw Data'!AE$4),"",'Raw Data'!AE$4) | H45: =IF(ISBLANK('Raw Data'!AE$5),"",'Raw Data'!AE$5) | I45: =IF(ISBLANK('Raw Data'!AE$6),"",'Raw Data'!AE$6) | J45: =IF(ISBLANK('Raw Data'!AE$7),"",'Raw Data'!AE$7) | K45: =IF(ISBLANK('Raw Data'!AE$8),"",'Raw Data'!AE$8) | L45: FALSE
C46: 30 | D46: =IF(ISBLANK('Raw Data'!AF$1),"",'Raw Data'!AF$1) | E46: =IF(ISBLANK('Raw Data'!AF$2),"",'Raw Data'!AF$2) | F46: =IF(ISBLANK('Raw Data'!AF$3),"",'Raw Data'!AF$3) | G46: =IF(ISBLANK('Raw Data'!AF$4),"",'Raw Data'!AF$4) | H46: =IF(ISBLANK('Raw Data'!AF$5),"",'Raw Data'!AF$5) | I46: =IF(ISBLANK('Raw Data'!AF$6),"",'Raw Data'!AF$6) | J46: =IF(ISBLANK('Raw Data'!AF$7),"",'Raw Data'!AF$7) | K46: =IF(ISBLANK('Raw Data'!AF$8),"",'Raw Data'!AF$8) | L46: FALSE
C47: 31 | D47: =IF(ISBLANK('Raw Data'!AG$1),"",'Raw Data'!AG$1) | E47: =IF(ISBLANK('Raw Data'!AG$2),"",'Raw Data'!AG$2) | F47: =IF(ISBLANK('Raw Data'!AG$3),"",'Raw Data'!AG$3) | G47: =IF(ISBLANK('Raw Data'!AG$4),"",'Raw Data'!AG$4) | H47: =IF(ISBLANK('Raw Data'!AG$5),"",'Raw Data'!AG$5) | I47: =IF(ISBLANK('Raw Data'!AG$6),"",'Raw Data'!AG$6) | J47: =IF(ISBLANK('Raw Data'!AG$7),"",'Raw Data'!AG$7) | K47: =IF(ISBLANK('Raw Data'!AG$8),"",'Raw Data'!AG$8) | L47: FALSE
C48: 32 | D48: =IF(ISBLANK('Raw Data'!AH$1),"",'Raw Data'!AH$1) | E48: =IF(ISBLANK('Raw Data'!AH$2),"",'Raw Data'!AH$2) | F48: =IF(ISBLANK('Raw Data'!AH$3),"",'Raw Data'!AH$3) | G48: =IF(ISBLANK('Raw Data'!AH$4),"",'Raw Data'!AH$4) | H48: =IF(ISBLANK('Raw Data'!AH$5),"",'Raw Data'!AH$5) | I48: =IF(ISBLANK('Raw Data'!AH$6),"",'Raw Data'!AH$6) | J48: =IF(ISBLANK('Raw Data'!AH$7),"",'Raw Data'!AH$7) | K48: =IF(ISBLANK('Raw Data'!AH$8),"",'Raw Data'!AH$8) | L48: FALSE
C49: 33 | D49: =IF(ISBLANK('Raw Data'!AI$1),"",'Raw Data'!AI$1) | E49: =IF(ISBLANK('Raw Data'!AI$2),"",'Raw Data'!AI$2) | F49: =IF(ISBLANK('Raw Data'!AI$3),"",'Raw Data'!AI$3) | G49: =IF(ISBLANK('Raw Data'!AI$4),"",'Raw Data'!AI$4) | H49: =IF(ISBLANK('Raw Data'!AI$5),"",'Raw Data'!AI$5) | I49: =IF(ISBLANK('Raw Data'!AI$6),"",'Raw Data'!AI$6) | J49: =IF(ISBLANK('Raw Data'!AI$7),"",'Raw Data'!AI$7) | K49: =IF(ISBLANK('Raw Data'!AI$8),"",'Raw Data'!AI$8) | L49: FALSE
C50: 34 | D50: =IF(ISBLANK('Raw Data'!AJ$1),"",'Raw Data'!AJ$1) | E50: =IF(ISBLANK('Raw Data'!AJ$2),"",'Raw Data'!AJ$2) | F50: =IF(ISBLANK('Raw Data'!AJ$3),"",'Raw Data'!AJ$3) | G50: =IF(ISBLANK('Raw Data'!AJ$4),"",'Raw Data'!AJ$4) | H50: =IF(ISBLANK('Raw Data'!AJ$5),"",'Raw Data'!AJ$5) | I50: =IF(ISBLANK('Raw Data'!AJ$6),"",'Raw Data'!AJ$6) | J50: =IF(ISBLANK('Raw Data'!AJ$7),"",'Raw Data'!AJ$7) | K50: =IF(ISBLANK('Raw Data'!AJ$8),"",'Raw Data'!AJ$8) | L50: FALSE
C51: 35 | D51: =IF(ISBLANK('Raw Data'!AK$1),"",'Raw Data'!AK$1) | E51: =IF(ISBLANK('Raw Data'!AK$2),"",'Raw Data'!AK$2) | F51: =IF(ISBLANK('Raw Data'!AK$3),"",'Raw Data'!AK$3) | G51: =IF(ISBLANK('Raw Data'!AK$4),"",'Raw Data'!AK$4) | H51: =IF(ISBLANK('Raw Data'!AK$5),"",'Raw Data'!AK$5) | I51: =IF(ISBLANK('Raw Data'!AK$6),"",'Raw Data'!AK$6) | J51: =IF(ISBLANK('Raw Data'!AK$7),"",'Raw Data'!AK$7) | K51: =IF(ISBLANK('Raw Data'!AK$8),"",'Raw Data'!AK$8) | L51: FALSE
C52: 36 | D52: =IF(ISBLANK('Raw Data'!AL$1),"",'Raw Data'!AL$1) | E52: =IF(ISBLANK('Raw Data'!AL$2),"",'Raw Data'!AL$2) | F52: =IF(ISBLANK('Raw Data'!AL$3),"",'Raw Data'!AL$3) | G52: =IF(ISBLANK('Raw Data'!AL$4),"",'Raw Data'!AL$4) | H52: =IF(ISBLANK('Raw Data'!AL$5),"",'Raw Data'!AL$5) | I52: =IF(ISBLANK('Raw Data'!AL$6),"",'Raw Data'!AL$6) | J52: =IF(ISBLANK('Raw Data'!AL$7),"",'Raw Data'!AL$7) | K52: =IF(ISBLANK('Raw Data'!AL$8),"",'Raw Data'!AL$8) | L52: FALSE
C53: 37 | D53: =IF(ISBLANK('Raw Data'!AM$1),"",'Raw Data'!AM$1) | E53: =IF(ISBLANK('Raw Data'!AM$2),"",'Raw Data'!AM$2) | F53: =IF(ISBLANK('Raw Data'!AM$3),"",'Raw Data'!AM$3) | G53: =IF(ISBLANK('Raw Data'!AM$4),"",'Raw Data'!AM$4) | H53: =IF(ISBLANK('Raw Data'!AM$5),"",'Raw Data'!AM$5) | I53: =IF(ISBLANK('Raw Data'!AM$6),"",'Raw Data'!AM$6) | J53: =IF(ISBLANK('Raw Data'!AM$7),"",'Raw Data'!AM$7) | K53: =IF(ISBLANK('Raw Data'!AM$8),"",'Raw Data'!AM$8) | L53: FALSE
C54: 38 | D54: =IF(ISBLANK('Raw Data'!AN$1),"",'Raw Data'!AN$1) | E54: =IF(ISBLANK('Raw Data'!AN$2),"",'Raw Data'!AN$2) | F54: =IF(ISBLANK('Raw Data'!AN$3),"",'Raw Data'!AN$3) | G54: =IF(ISBLANK('Raw Data'!AN$4),"",'Raw Data'!AN$4) | H54: =IF(ISBLANK('Raw Data'!AN$5),"",'Raw Data'!AN$5) | I54: =IF(ISBLANK('Raw Data'!AN$6),"",'Raw Data'!AN$6) | J54: =IF(ISBLANK('Raw Data'!AN$7),"",'Raw Data'!AN$7) | K54: =IF(ISBLANK('Raw Data'!AN$8),"",'Raw Data'!AN$8) | L54: FALSE
C55: 39 | D55: =IF(ISBLANK('Raw Data'!AO$1),"",'Raw Data'!AO$1) | E55: =IF(ISBLANK('Raw Data'!AO$2),"",'Raw Data'!AO$2) | F55: =IF(ISBLANK('Raw Data'!AO$3),"",'Raw Data'!AO$3) | G55: =IF(ISBLANK('Raw Data'!AO$4),"",'Raw Data'!AO$4) | H55: =IF(ISBLANK('Raw Data'!AO$5),"",'Raw Data'!AO$5) | I55: =IF(ISBLANK('Raw Data'!AO$6),"",'Raw Data'!AO$6) | J55: =IF(ISBLANK('Raw Data'!AO$7),"",'Raw Data'!AO$7) | K55: =IF(ISBLANK('Raw Data'!AO$8),"",'Raw Data'!AO$8) | L55: FALSE
...

Sheet Raw Data
B1: Time
B2: Date
B3: Cassette Identifier Code
B4: Sample ID
B5: Result
B6: Method
B7: Version
B8: Lot Code
B9: 1
B10: 2
B11: 3
B12: 4
B13: 5
B14: 6
B15: 7
B16: 8
B17: 9
B18: 10
B19: 11
B20: 12
... B288: 280

Sheet Presented Data
B1: Time
B2: Date
B3: Cassette Identifier Code
B4: Sample ID | C4: =IF(Results!$L17=TRUE,'Raw Data'!C4,"") -> 0 | D4: =IF(Results!$L18=TRUE,'Raw Data'!D4,"") -> 0 | E4: =IF(Results!$L19=TRUE,'Raw Data'!E4,"") | F4: =IF(Results!$L20=TRUE,'Raw Data'!F4,"") | G4: =IF(Results!$L21=TRUE,'Raw Data'!G4,"") | H4: =IF(Results!$L22=TRUE,'Raw Data'!H4,"") | I4: =IF(Results!$L23=TRUE,'Raw Data'!I4,"") | J4: =IF(Results!$L24=TRUE,'Raw Data'!J4,"") | K4: =IF(Results!$L25=TRUE,'Raw Data'!K4,"") | L4: =IF(Results!$L26=TRUE,'Raw Data'!L4,"") | M4: =IF(Results!$L27=TRUE,'Raw Data'!M4,"") | N4: =IF(Results!$L28=TRUE,'Raw Data'!N4,"") | O4: =IF(Results!$L29=TRUE,'Raw Data'!O4,"") | P4: =IF(Results!$L30=TRUE,'Raw Data'!P4,"") | Q4: =IF(Results!$L31=TRUE,'Raw Data'!Q4,"") | R4: =IF(Results!$L32=TRUE,'Raw Data'!R4,"") | S4: =IF(Results!$L33=TRUE,'Raw Data'!S4,"") | T4: =IF(Results!$L34=TRUE,'Raw Data'!T4,"") | U4: =IF(Results!$L35=TRUE,'Raw Data'!U4,"") | V4: =IF(Results!$L36=TRUE,'Raw Data'!V4,"") | W4: =IF(Results!$L37=TRUE,'Raw Data'!W4,"") | X4: =IF(Results!$L38=TRUE,'Raw Data'!X4,"") | Y4: =IF(Results!$L39=TRUE,'Raw Data'!Y4,"") | Z4: =IF(Results!$L40=TRUE,'Raw Data'!Z4,"") | AA4: =IF(Results!$L41=TRUE,'Raw Data'!AA4,"") | AB4: =IF(Results!$L42=TRUE,'Raw Data'!AB4,"") | AC4: =IF(Results!$L43=TRUE,'Raw Data'!AC4,"") | AD4: =IF(Results!$L44=TRUE,'Raw Data'!AD4,"") | AE4: =IF(Results!$L45=TRUE,'Raw Data'!AE4,"") | AF4: =IF(Results!$L46=TRUE,'Raw Data'!AF4,"") | AG4: =IF(Results!$L47=TRUE,'Raw Data'!AG4,"") | AH4: =IF(Results!$L48=TRUE,'Raw Data'!AH4,"") | AI4: =IF(Results!$L49=TRUE,'Raw Data'!AI4,"") | AJ4: =IF(Results!$L50=TRUE,'Raw Data'!AJ4,"") | AK4: =IF(Results!$L51=TRUE,'Raw Data'!AK4,"") | AL4: =IF(Results!$L52=TRUE,'Raw Data'!AL4,"") | AM4: =IF(Results!$L53=TRUE,'Raw Data'!AM4,"") | AN4: =IF(Results!$L54=TRUE,'Raw Data'!AN4,"") | AO4: =IF(Results!$L55=TRUE,'Raw Data'!AO4,"") | AP4: =IF(Results!$L56=TRUE,'Raw Data'!AP4,"")
B5: Result
B6: Method
B7: Lot Code
B8: Data | C8: Graph title | D8: =SUBSTITUTE(_xlfn.TEXTJOIN(", ",TRUE,'Presented Data'!C4:AP4),","," and",MAX(1,COUNTA('Presented Data'!C4:AP4)-1)) -> 0, 0
B9: 1 | C9: =IF(Results!$L$17=TRUE,'Raw Data'!C9-'Raw Data'!C$9,"") -> 0 | D9: =IF(Results!$L$18=TRUE,'Raw Data'!D9-'Raw Data'!D$9,"") -> 0 | E9: =IF(Results!$L$19=TRUE,'Raw Data'!E9-'Raw Data'!E$9,"") | F9: =IF(Results!$L$20=TRUE,'Raw Data'!F9-'Raw Data'!F$9,"") | G9: =IF(Results!$L$21=TRUE,'Raw Data'!G9-'Raw Data'!G$9,"") | H9: =IF(Results!$L$22=TRUE,'Raw Data'!H9-'Raw Data'!H$9,"") | I9: =IF(Results!$L$23=TRUE,'Raw Data'!I9-'Raw Data'!I$9,"") | J9: =IF(Results!$L$24=TRUE,'Raw Data'!J9-'Raw Data'!J$9,"") | K9: =IF(Results!$L$25=TRUE,'Raw Data'!K9-'Raw Data'!K$9,"") | L9: =IF(Results!$L$26=TRUE,'Raw Data'!L9-'Raw Data'!L$9,"") | M9: =IF(Results!$L$27=TRUE,'Raw Data'!M9-'Raw Data'!M$9,"") | N9: =IF(Results!$L$28=TRUE,'Raw Data'!N9-'Raw Data'!N$9,"") | O9: =IF(Results!$L$29=TRUE,'Raw Data'!O9-'Raw Data'!O$9,"") | P9: =IF(Results!$L$30=TRUE,'Raw Data'!P9-'Raw Data'!P$9,"") | Q9: =IF(Results!$L$31=TRUE,'Raw Data'!Q9-'Raw Data'!Q$9,"") | R9: =IF(Results!$L$32=TRUE,'Raw Data'!R9-'Raw Data'!R$9,"") | S9: =IF(Results!$L$33=TRUE,'Raw Data'!S9-'Raw Data'!S$9,"") | T9: =IF(Results!$L$34=TRUE,'Raw Data'!T9-'Raw Data'!T$9,"") | U9: =IF(Results!$L$35=TRUE,'Raw Data'!U9-'Raw Data'!U$9,"") | V9: =IF(Results!$L$36=TRUE,'Raw Data'!V9-'Raw Data'!V$9,"") | W9: =IF(Results!$L$37=TRUE,'Raw Data'!W9-'Raw Data'!W$9,"") | X9: =IF(Results!$L$38=TRUE,'Raw Data'!X9-'Raw Data'!X$9,"") | Y9: =IF(Results!$L$39=TRUE,'Raw Data'!Y9-'Raw Data'!Y$9,"") | Z9: =IF(Results!$L$40=TRUE,'Raw Data'!Z9-'Raw Data'!Z$9,"") | AA9: =IF(Results!$L$41=TRUE,'Raw Data'!AA9-'Raw Data'!AA$9,"") | AB9: =IF(Results!$L$42=TRUE,'Raw Data'!AB9-'Raw Data'!AB$9,"") | AC9: =IF(Results!$L$43=TRUE,'Raw Data'!AC9-'Raw Data'!AC$9,"") | AD9: =IF(Results!$L$44=TRUE,'Raw Data'!AD9-'Raw Data'!AD$9,"") | AE9: =IF(Results!$L$45=TRUE,'Raw Data'!AE9-'Raw Data'!AE$9,"") | AF9: =IF(Results!$L$46=TRUE,'Raw Data'!AF9-'Raw Data'!AF$9,"") | AG9: =IF(Results!$L$47=TRUE,'Raw Data'!AG9-'Raw Data'!AG$9,"") | AH9: =IF(Results!$L$48=TRUE,'Raw Data'!AH9-'Raw Data'!AH$9,"") | AI9: =IF(Results!$L$49=TRUE,'Raw Data'!AI9-'Raw Data'!AI$9,"") | AJ9: =IF(Results!$L$50=TRUE,'Raw Data'!AJ9-'Raw Data'!AJ$9,"") | AK9: =IF(Results!$L$51=TRUE,'Raw Data'!AK9-'Raw Data'!AK$9,"") | AL9: =IF(Results!$L$52=TRUE,'Raw Data'!AL9-'Raw Data'!AL$9,"") | AM9: =IF(Results!$L$53=TRUE,'Raw Data'!AM9-'Raw Data'!AM$9,"") | AN9: =IF(Results!$L$54=TRUE,'Raw Data'!AN9-'Raw Data'!AN$9,"") | AO9: =IF(Results!$L$55=TRUE,'Raw Data'!AO9-'Raw Data'!AO$9,"") | AP9: =IF(Results!$L$56=TRUE,'Raw Data'!AP9-'Raw Data'!AP$9,"")
B10: 2 | C10: =IF(Results!$L$17=TRUE,'Raw Data'!C10-'Raw Data'!C$9,"") -> 0 | D10: =IF(Results!$L$18=TRUE,'Raw Data'!D10-'Raw Data'!D$9,"") -> 0 | E10: =IF(Results!$L$19=TRUE,'Raw Data'!E10-'Raw Data'!E$9,"") | F10: =IF(Results!$L$20=TRUE,'Raw Data'!F10-'Raw Data'!F$9,"") | G10: =IF(Results!$L$21=TRUE,'Raw Data'!G10-'Raw Data'!G$9,"") | H10: =IF(Results!$L$22=TRUE,'Raw Data'!H10-'Raw Data'!H$9,"") | I10: =IF(Results!$L$23=TRUE,'Raw Data'!I10-'Raw Data'!I$9,"") | J10: =IF(Results!$L$24=TRUE,'Raw Data'!J10-'Raw Data'!J$9,"") | K10: =IF(Results!$L$25=TRUE,'Raw Data'!K10-'Raw Data'!K$9,"") | L10: =IF(Results!$L$26=TRUE,'Raw Data'!L10-'Raw Data'!L$9,"") | M10: =IF(Results!$L$27=TRUE,'Raw Data'!M10-'Raw Data'!M$9,"") | N10: =IF(Results!$L$28=TRUE,'Raw Data'!N10-'Raw Data'!N$9,"") | O10: =IF(Results!$L$29=TRUE,'Raw Data'!O10-'Raw Data'!O$9,"") | P10: =IF(Results!$L$30=TRUE,'Raw Data'!P10-'Raw Data'!P$9,"") | Q10: =IF(Results!$L$31=TRUE,'Raw Data'!Q10-'Raw Data'!Q$9,"") | R10: =IF(Results!$L$32=TRUE,'Raw Data'!R10-'Raw Data'!R$9,"") | S10: =IF(Results!$L$33=TRUE,'Raw Data'!S10-'Raw Data'!S$9,"") | T10: =IF(Results!$L$34=TRUE,'Raw Data'!T10-'Raw Data'!T$9,"") | U10: =IF(Results!$L$35=TRUE,'Raw Data'!U10-'Raw Data'!U$9,"") | V10: =IF(Results!$L$36=TRUE,'Raw Data'!V10-'Raw Data'!V$9,"") | W10: =IF(Results!$L$37=TRUE,'Raw Data'!W10-'Raw Data'!W$9,"") | X10: =IF(Results!$L$38=TRUE,'Raw Data'!X10-'Raw Data'!X$9,"") | Y10: =IF(Results!$L$39=TRUE,'Raw Data'!Y10-'Raw Data'!Y$9,"") | Z10: =IF(Results!$L$40=TRUE,'Raw Data'!Z10-'Raw Data'!Z$9,"") | AA10: =IF(Results!$L$41=TRUE,'Raw Data'!AA10-'Raw Data'!AA$9,"") | AB10: =IF(Results!$L$42=TRUE,'Raw Data'!AB10-'Raw Data'!AB$9,"") | AC10: =IF(Results!$L$43=TRUE,'Raw Data'!AC10-'Raw Data'!AC$9,"") | AD10: =IF(Results!$L$44=TRUE,'Raw Data'!AD10-'Raw Data'!AD$9,"") | AE10: =IF(Results!$L$45=TRUE,'Raw Data'!AE10-'Raw Data'!AE$9,"") | AF10: =IF(Results!$L$46=TRUE,'Raw Data'!AF10-'Raw Data'!AF$9,"") | AG10: =IF(Results!$L$47=TRUE,'Raw Data'!AG10-'Raw Data'!AG$9,"") | AH10: =IF(Results!$L$48=TRUE,'Raw Data'!AH10-'Raw Data'!AH$9,"") | AI10: =IF(Results!$L$49=TRUE,'Raw Data'!AI10-'Raw Data'!AI$9,"") | AJ10: =IF(Results!$L$50=TRUE,'Raw Data'!AJ10-'Raw Data'!AJ$9,"") | AK10: =IF(Results!$L$51=TRUE,'Raw Data'!AK10-'Raw Data'!AK$9,"") | AL10: =IF(Results!$L$52=TRUE,'Raw Data'!AL10-'Raw Data'!AL$9,"") | AM10: =IF(Results!$L$53=TRUE,'Raw Data'!AM10-'Raw Data'!AM$9,"") | AN10: =IF(Results!$L$54=TRUE,'Raw Data'!AN10-'Raw Data'!AN$9,"") | AO10: =IF(Results!$L$55=TRUE,'Raw Data'!AO10-'Raw Data'!AO$9,"") | AP10: =IF(Results!$L$56=TRUE,'Raw Data'!AP10-'Raw Data'!AP$9,"")
B11: 3 | C11: =IF(Results!$L$17=TRUE,'Raw Data'!C11-'Raw Data'!C$9,"") -> 0 | D11: =IF(Results!$L$18=TRUE,'Raw Data'!D11-'Raw Data'!D$9,"") -> 0 | E11: =IF(Results!$L$19=TRUE,'Raw Data'!E11-'Raw Data'!E$9,"") | F11: =IF(Results!$L$20=TRUE,'Raw Data'!F11-'Raw Data'!F$9,"") | G11: =IF(Results!$L$21=TRUE,'Raw Data'!G11-'Raw Data'!G$9,"") | H11: =IF(Results!$L$22=TRUE,'Raw Data'!H11-'Raw Data'!H$9,"") | I11: =IF(Results!$L$23=TRUE,'Raw Data'!I11-'Raw Data'!I$9,"") | J11: =IF(Results!$L$24=TRUE,'Raw Data'!J11-'Raw Data'!J$9,"") | K11: =IF(Results!$L$25=TRUE,'Raw Data'!K11-'Raw Data'!K$9,"") | L11: =IF(Results!$L$26=TRUE,'Raw Data'!L11-'Raw Data'!L$9,"") | M11: =IF(Results!$L$27=TRUE,'Raw Data'!M11-'Raw Data'!M$9,"") | N11: =IF(Results!$L$28=TRUE,'Raw Data'!N11-'Raw Data'!N$9,"") | O11: =IF(Results!$L$29=TRUE,'Raw Data'!O11-'Raw Data'!O$9,"") | P11: =IF(Results!$L$30=TRUE,'Raw Data'!P11-'Raw Data'!P$9,"") | Q11: =IF(Results!$L$31=TRUE,'Raw Data'!Q11-'Raw Data'!Q$9,"") | R11: =IF(Results!$L$32=TRUE,'Raw Data'!R11-'Raw Data'!R$9,"") | S11: =IF(Results!$L$33=TRUE,'Raw Data'!S11-'Raw Data'!S$9,"") | T11: =IF(Results!$L$34=TRUE,'Raw Data'!T11-'Raw Data'!T$9,"") | U11: =IF(Results!$L$35=TRUE,'Raw Data'!U11-'Raw Data'!U$9,"") | V11: =IF(Results!$L$36=TRUE,'Raw Data'!V11-'Raw Data'!V$9,"") | W11: =IF(Results!$L$37=TRUE,'Raw Data'!W11-'Raw Data'!W$9,"") | X11: =IF(Results!$L$38=TRUE,'Raw Data'!X11-'Raw Data'!X$9,"") | Y11: =IF(Results!$L$39=TRUE,'Raw Data'!Y11-'Raw Data'!Y$9,"") | Z11: =IF(Results!$L$40=TRUE,'Raw Data'!Z11-'Raw Data'!Z$9,"") | AA11: =IF(Results!$L$41=TRUE,'Raw Data'!AA11-'Raw Data'!AA$9,"") | AB11: =IF(Results!$L$42=TRUE,'Raw Data'!AB11-'Raw Data'!AB$9,"") | AC11: =IF(Results!$L$43=TRUE,'Raw Data'!AC11-'Raw Data'!AC$9,"") | AD11: =IF(Results!$L$44=TRUE,'Raw Data'!AD11-'Raw Data'!AD$9,"") | AE11: =IF(Results!$L$45=TRUE,'Raw Data'!AE11-'Raw Data'!AE$9,"") | AF11: =IF(Results!$L$46=TRUE,'Raw Data'!AF11-'Raw Data'!AF$9,"") | AG11: =IF(Results!$L$47=TRUE,'Raw Data'!AG11-'Raw Data'!AG$9,"") | AH11: =IF(Results!$L$48=TRUE,'Raw Data'!AH11-'Raw Data'!AH$9,"") | AI11: =IF(Results!$L$49=TRUE,'Raw Data'!AI11-'Raw Data'!AI$9,"") | AJ11: =IF(Results!$L$50=TRUE,'Raw Data'!AJ11-'Raw Data'!AJ$9,"") | AK11: =IF(Results!$L$51=TRUE,'Raw Data'!AK11-'Raw Data'!AK$9,"") | AL11: =IF(Results!$L$52=TRUE,'Raw Data'!AL11-'Raw Data'!AL$9,"") | AM11: =IF(Results!$L$53=TRUE,'Raw Data'!AM11-'Raw Data'!AM$9,"") | AN11: =IF(Results!$L$54=TRUE,'Raw Data'!AN11-'Raw Data'!AN$9,"") | AO11: =IF(Results!$L$55=TRUE,'Raw Data'!AO11-'Raw Data'!AO$9,"") | AP11: =IF(Results!$L$56=TRUE,'Raw Data'!AP11-'Raw Data'!AP$9,"")
B12: 4 | C12: =IF(Results!$L$17=TRUE,'Raw Data'!C12-'Raw Data'!C$9,"") -> 0 | D12: =IF(Results!$L$18=TRUE,'Raw Data'!D12-'Raw Data'!D$9,"") -> 0 | E12: =IF(Results!$L$19=TRUE,'Raw Data'!E12-'Raw Data'!E$9,"") | F12: =IF(Results!$L$20=TRUE,'Raw Data'!F12-'Raw Data'!F$9,"") | G12: =IF(Results!$L$21=TRUE,'Raw Data'!G12-'Raw Data'!G$9,"") | H12: =IF(Results!$L$22=TRUE,'Raw Data'!H12-'Raw Data'!H$9,"") | I12: =IF(Results!$L$23=TRUE,'Raw Data'!I12-'Raw Data'!I$9,"") | J12: =IF(Results!$L$24=TRUE,'Raw Data'!J12-'Raw Data'!J$9,"") | K12: =IF(Results!$L$25=TRUE,'Raw Data'!K12-'Raw Data'!K$9,"") | L12: =IF(Results!$L$26=TRUE,'Raw Data'!L12-'Raw Data'!L$9,"") | M12: =IF(Results!$L$27=TRUE,'Raw Data'!M12-'Raw Data'!M$9,"") | N12: =IF(Results!$L$28=TRUE,'Raw Data'!N12-'Raw Data'!N$9,"") | O12: =IF(Results!$L$29=TRUE,'Raw Data'!O12-'Raw Data'!O$9,"") | P12: =IF(Results!$L$30=TRUE,'Raw Data'!P12-'Raw Data'!P$9,"") | Q12: =IF(Results!$L$31=TRUE,'Raw Data'!Q12-'Raw Data'!Q$9,"") | R12: =IF(Results!$L$32=TRUE,'Raw Data'!R12-'Raw Data'!R$9,"") | S12: =IF(Results!$L$33=TRUE,'Raw Data'!S12-'Raw Data'!S$9,"") | T12: =IF(Results!$L$34=TRUE,'Raw Data'!T12-'Raw Data'!T$9,"") | U12: =IF(Results!$L$35=TRUE,'Raw Data'!U12-'Raw Data'!U$9,"") | V12: =IF(Results!$L$36=TRUE,'Raw Data'!V12-'Raw Data'!V$9,"") | W12: =IF(Results!$L$37=TRUE,'Raw Data'!W12-'Raw Data'!W$9,"") | X12: =IF(Results!$L$38=TRUE,'Raw Data'!X12-'Raw Data'!X$9,"") | Y12: =IF(Results!$L$39=TRUE,'Raw Data'!Y12-'Raw Data'!Y$9,"") | Z12: =IF(Results!$L$40=TRUE,'Raw Data'!Z12-'Raw Data'!Z$9,"") | AA12: =IF(Results!$L$41=TRUE,'Raw Data'!AA12-'Raw Data'!AA$9,"") | AB12: =IF(Results!$L$42=TRUE,'Raw Data'!AB12-'Raw Data'!AB$9,"") | AC12: =IF(Results!$L$43=TRUE,'Raw Data'!AC12-'Raw Data'!AC$9,"") | AD12: =IF(Results!$L$44=TRUE,'Raw Data'!AD12-'Raw Data'!AD$9,"") | AE12: =IF(Results!$L$45=TRUE,'Raw Data'!AE12-'Raw Data'!AE$9,"") | AF12: =IF(Results!$L$46=TRUE,'Raw Data'!AF12-'Raw Data'!AF$9,"") | AG12: =IF(Results!$L$47=TRUE,'Raw Data'!AG12-'Raw Data'!AG$9,"") | AH12: =IF(Results!$L$48=TRUE,'Raw Data'!AH12-'Raw Data'!AH$9,"") | AI12: =IF(Results!$L$49=TRUE,'Raw Data'!AI12-'Raw Data'!AI$9,"") | AJ12: =IF(Results!$L$50=TRUE,'Raw Data'!AJ12-'Raw Data'!AJ$9,"") | AK12: =IF(Results!$L$51=TRUE,'Raw Data'!AK12-'Raw Data'!AK$9,"") | AL12: =IF(Results!$L$52=TRUE,'Raw Data'!AL12-'Raw Data'!AL$9,"") | AM12: =IF(Results!$L$53=TRUE,'Raw Data'!AM12-'Raw Data'!AM$9,"") | AN12: =IF(Results!$L$54=TRUE,'Raw Data'!AN12-'Raw Data'!AN$9,"") | AO12: =IF(Results!$L$55=TRUE,'Raw Data'!AO12-'Raw Data'!AO$9,"") | AP12: =IF(Results!$L$56=TRUE,'Raw Data'!AP12-'Raw Data'!AP$9,"")
B13: 5 | C13: =IF(Results!$L$17=TRUE,'Raw Data'!C13-'Raw Data'!C$9,"") -> 0 | D13: =IF(Results!$L$18=TRUE,'Raw Data'!D13-'Raw Data'!D$9,"") -> 0 | E13: =IF(Results!$L$19=TRUE,'Raw Data'!E13-'Raw Data'!E$9,"") | F13: =IF(Results!$L$20=TRUE,'Raw Data'!F13-'Raw Data'!F$9,"") | G13: =IF(Results!$L$21=TRUE,'Raw Data'!G13-'Raw Data'!G$9,"") | H13: =IF(Results!$L$22=TRUE,'Raw Data'!H13-'Raw Data'!H$9,"") | I13: =IF(Results!$L$23=TRUE,'Raw Data'!I13-'Raw Data'!I$9,"") | J13: =IF(Results!$L$24=TRUE,'Raw Data'!J13-'Raw Data'!J$9,"") | K13: =IF(Results!$L$25=TRUE,'Raw Data'!K13-'Raw Data'!K$9,"") | L13: =IF(Results!$L$26=TRUE,'Raw Data'!L13-'Raw Data'!L$9,"") | M13: =IF(Results!$L$27=TRUE,'Raw Data'!M13-'Raw Data'!M$9,"") | N13: =IF(Results!$L$28=TRUE,'Raw Data'!N13-'Raw Data'!N$9,"") | O13: =IF(Results!$L$29=TRUE,'Raw Data'!O13-'Raw Data'!O$9,"") | P13: =IF(Results!$L$30=TRUE,'Raw Data'!P13-'Raw Data'!P$9,"") | Q13: =IF(Results!$L$31=TRUE,'Raw Data'!Q13-'Raw Data'!Q$9,"") | R13: =IF(Results!$L$32=TRUE,'Raw Data'!R13-'Raw Data'!R$9,"") | S13: =IF(Results!$L$33=TRUE,'Raw Data'!S13-'Raw Data'!S$9,"") | T13: =IF(Results!$L$34=TRUE,'Raw Data'!T13-'Raw Data'!T$9,"") | U13: =IF(Results!$L$35=TRUE,'Raw Data'!U13-'Raw Data'!U$9,"") | V13: =IF(Results!$L$36=TRUE,'Raw Data'!V13-'Raw Data'!V$9,"") | W13: =IF(Results!$L$37=TRUE,'Raw Data'!W13-'Raw Data'!W$9,"") | X13: =IF(Results!$L$38=TRUE,'Raw Data'!X13-'Raw Data'!X$9,"") | Y13: =IF(Results!$L$39=TRUE,'Raw Data'!Y13-'Raw Data'!Y$9,"") | Z13: =IF(Results!$L$40=TRUE,'Raw Data'!Z13-'Raw Data'!Z$9,"") | AA13: =IF(Results!$L$41=TRUE,'Raw Data'!AA13-'Raw Data'!AA$9,"") | AB13: =IF(Results!$L$42=TRUE,'Raw Data'!AB13-'Raw Data'!AB$9,"") | AC13: =IF(Results!$L$43=TRUE,'Raw Data'!AC13-'Raw Data'!AC$9,"") | AD13: =IF(Results!$L$44=TRUE,'Raw Data'!AD13-'Raw Data'!AD$9,"") | AE13: =IF(Results!$L$45=TRUE,'Raw Data'!AE13-'Raw Data'!AE$9,"") | AF13: =IF(Results!$L$46=TRUE,'Raw Data'!AF13-'Raw Data'!AF$9,"") | AG13: =IF(Results!$L$47=TRUE,'Raw Data'!AG13-'Raw Data'!AG$9,"") | AH13: =IF(Results!$L$48=TRUE,'Raw Data'!AH13-'Raw Data'!AH$9,"") | AI13: =IF(Results!$L$49=TRUE,'Raw Data'!AI13-'Raw Data'!AI$9,"") | AJ13: =IF(Results!$L$50=TRUE,'Raw Data'!AJ13-'Raw Data'!AJ$9,"") | AK13: =IF(Results!$L$51=TRUE,'Raw Data'!AK13-'Raw Data'!AK$9,"") | AL13: =IF(Results!$L$52=TRUE,'Raw Data'!AL13-'Raw Data'!AL$9,"") | AM13: =IF(Results!$L$53=TRUE,'Raw Data'!AM13-'Raw Data'!AM$9,"") | AN13: =IF(Results!$L$54=TRUE,'Raw Data'!AN13-'Raw Data'!AN$9,"") | AO13: =IF(Results!$L$55=TRUE,'Raw Data'!AO13-'Raw Data'!AO$9,"") | AP13: =IF(Results!$L$56=TRUE,'Raw Data'!AP13-'Raw Data'!AP$9,"")
B14: 6 | C14: =IF(Results!$L$17=TRUE,'Raw Data'!C14-'Raw Data'!C$9,"") -> 0 | D14: =IF(Results!$L$18=TRUE,'Raw Data'!D14-'Raw Data'!D$9,"") -> 0 | E14: =IF(Results!$L$19=TRUE,'Raw Data'!E14-'Raw Data'!E$9,"") | F14: =IF(Results!$L$20=TRUE,'Raw Data'!F14-'Raw Data'!F$9,"") | G14: =IF(Results!$L$21=TRUE,'Raw Data'!G14-'Raw Data'!G$9,"") | H14: =IF(Results!$L$22=TRUE,'Raw Data'!H14-'Raw Data'!H$9,"") | I14: =IF(Results!$L$23=TRUE,'Raw Data'!I14-'Raw Data'!I$9,"") | J14: =IF(Results!$L$24=TRUE,'Raw Data'!J14-'Raw Data'!J$9,"") | K14: =IF(Results!$L$25=TRUE,'Raw Data'!K14-'Raw Data'!K$9,"") | L14: =IF(Results!$L$26=TRUE,'Raw Data'!L14-'Raw Data'!L$9,"") | M14: =IF(Results!$L$27=TRUE,'Raw Data'!M14-'Raw Data'!M$9,"") | N14: =IF(Results!$L$28=TRUE,'Raw Data'!N14-'Raw Data'!N$9,"") | O14: =IF(Results!$L$29=TRUE,'Raw Data'!O14-'Raw Data'!O$9,"") | P14: =IF(Results!$L$30=TRUE,'Raw Data'!P14-'Raw Data'!P$9,"") | Q14: =IF(Results!$L$31=TRUE,'Raw Data'!Q14-'Raw Data'!Q$9,"") | R14: =IF(Results!$L$32=TRUE,'Raw Data'!R14-'Raw Data'!R$9,"") | S14: =IF(Results!$L$33=TRUE,'Raw Data'!S14-'Raw Data'!S$9,"") | T14: =IF(Results!$L$34=TRUE,'Raw Data'!T14-'Raw Data'!T$9,"") | U14: =IF(Results!$L$35=TRUE,'Raw Data'!U14-'Raw Data'!U$9,"") | V14: =IF(Results!$L$36=TRUE,'Raw Data'!V14-'Raw Data'!V$9,"") | W14: =IF(Results!$L$37=TRUE,'Raw Data'!W14-'Raw Data'!W$9,"") | X14: =IF(Results!$L$38=TRUE,'Raw Data'!X14-'Raw Data'!X$9,"") | Y14: =IF(Results!$L$39=TRUE,'Raw Data'!Y14-'Raw Data'!Y$9,"") | Z14: =IF(Results!$L$40=TRUE,'Raw Data'!Z14-'Raw Data'!Z$9,"") | AA14: =IF(Results!$L$41=TRUE,'Raw Data'!AA14-'Raw Data'!AA$9,"") | AB14: =IF(Results!$L$42=TRUE,'Raw Data'!AB14-'Raw Data'!AB$9,"") | AC14: =IF(Results!$L$43=TRUE,'Raw Data'!AC14-'Raw Data'!AC$9,"") | AD14: =IF(Results!$L$44=TRUE,'Raw Data'!AD14-'Raw Data'!AD$9,"") | AE14: =IF(Results!$L$45=TRUE,'Raw Data'!AE14-'Raw Data'!AE$9,"") | AF14: =IF(Results!$L$46=TRUE,'Raw Data'!AF14-'Raw Data'!AF$9,"") | AG14: =IF(Results!$L$47=TRUE,'Raw Data'!AG14-'Raw Data'!AG$9,"") | AH14: =IF(Results!$L$48=TRUE,'Raw Data'!AH14-'Raw Data'!AH$9,"") | AI14: =IF(Results!$L$49=TRUE,'Raw Data'!AI14-'Raw Data'!AI$9,"") | AJ14: =IF(Results!$L$50=TRUE,'Raw Data'!AJ14-'Raw Data'!AJ$9,"") | AK14: =IF(Results!$L$51=TRUE,'Raw Data'!AK14-'Raw Data'!AK$9,"") | AL14: =IF(Results!$L$52=TRUE,'Raw Data'!AL14-'Raw Data'!AL$9,"") | AM14: =IF(Results!$L$53=TRUE,'Raw Data'!AM14-'Raw Data'!AM$9,"") | AN14: =IF(Results!$L$54=TRUE,'Raw Data'!AN14-'Raw Data'!AN$9,"") | AO14: =IF(Results!$L$55=TRUE,'Raw Data'!AO14-'Raw Data'!AO$9,"") | AP14: =IF(Results!$L$56=TRUE,'Raw Data'!AP14-'Raw Data'!AP$9,"")
B15: 7 | C15: =IF(Results!$L$17=TRUE,'Raw Data'!C15-'Raw Data'!C$9,"") -> 0 | D15: =IF(Results!$L$18=TRUE,'Raw Data'!D15-'Raw Data'!D$9,"") -> 0 | E15: =IF(Results!$L$19=TRUE,'Raw Data'!E15-'Raw Data'!E$9,"") | F15: =IF(Results!$L$20=TRUE,'Raw Data'!F15-'Raw Data'!F$9,"") | G15: =IF(Results!$L$21=TRUE,'Raw Data'!G15-'Raw Data'!G$9,"") | H15: =IF(Results!$L$22=TRUE,'Raw Data'!H15-'Raw Data'!H$9,"") | I15: =IF(Results!$L$23=TRUE,'Raw Data'!I15-'Raw Data'!I$9,"") | J15: =IF(Results!$L$24=TRUE,'Raw Data'!J15-'Raw Data'!J$9,"") | K15: =IF(Results!$L$25=TRUE,'Raw Data'!K15-'Raw Data'!K$9,"") | L15: =IF(Results!$L$26=TRUE,'Raw Data'!L15-'Raw Data'!L$9,"") | M15: =IF(Results!$L$27=TRUE,'Raw Data'!M15-'Raw Data'!M$9,"") | N15: =IF(Results!$L$28=TRUE,'Raw Data'!N15-'Raw Data'!N$9,"") | O15: =IF(Results!$L$29=TRUE,'Raw Data'!O15-'Raw Data'!O$9,"") | P15: =IF(Results!$L$30=TRUE,'Raw Data'!P15-'Raw Data'!P$9,"") | Q15: =IF(Results!$L$31=TRUE,'Raw Data'!Q15-'Raw Data'!Q$9,"") | R15: =IF(Results!$L$32=TRUE,'Raw Data'!R15-'Raw Data'!R$9,"") | S15: =IF(Results!$L$33=TRUE,'Raw Data'!S15-'Raw Data'!S$9,"") | T15: =IF(Results!$L$34=TRUE,'Raw Data'!T15-'Raw Data'!T$9,"") | U15: =IF(Results!$L$35=TRUE,'Raw Data'!U15-'Raw Data'!U$9,"") | V15: =IF(Results!$L$36=TRUE,'Raw Data'!V15-'Raw Data'!V$9,"") | W15: =IF(Results!$L$37=TRUE,'Raw Data'!W15-'Raw Data'!W$9,"") | X15: =IF(Results!$L$38=TRUE,'Raw Data'!X15-'Raw Data'!X$9,"") | Y15: =IF(Results!$L$39=TRUE,'Raw Data'!Y15-'Raw Data'!Y$9,"") | Z15: =IF(Results!$L$40=TRUE,'Raw Data'!Z15-'Raw Data'!Z$9,"") | AA15: =IF(Results!$L$41=TRUE,'Raw Data'!AA15-'Raw Data'!AA$9,"") | AB15: =IF(Results!$L$42=TRUE,'Raw Data'!AB15-'Raw Data'!AB$9,"") | AC15: =IF(Results!$L$43=TRUE,'Raw Data'!AC15-'Raw Data'!AC$9,"") | AD15: =IF(Results!$L$44=TRUE,'Raw Data'!AD15-'Raw Data'!AD$9,"") | AE15: =IF(Results!$L$45=TRUE,'Raw Data'!AE15-'Raw Data'!AE$9,"") | AF15: =IF(Results!$L$46=TRUE,'Raw Data'!AF15-'Raw Data'!AF$9,"") | AG15: =IF(Results!$L$47=TRUE,'Raw Data'!AG15-'Raw Data'!AG$9,"") | AH15: =IF(Results!$L$48=TRUE,'Raw Data'!AH15-'Raw Data'!AH$9,"") | AI15: =IF(Results!$L$49=TRUE,'Raw Data'!AI15-'Raw Data'!AI$9,"") | AJ15: =IF(Results!$L$50=TRUE,'Raw Data'!AJ15-'Raw Data'!AJ$9,"") | AK15: =IF(Results!$L$51=TRUE,'Raw Data'!AK15-'Raw Data'!AK$9,"") | AL15: =IF(Results!$L$52=TRUE,'Raw Data'!AL15-'Raw Data'!AL$9,"") | AM15: =IF(Results!$L$53=TRUE,'Raw Data'!AM15-'Raw Data'!AM$9,"") | AN15: =IF(Results!$L$54=TRUE,'Raw Data'!AN15-'Raw Data'!AN$9,"") | AO15: =IF(Results!$L$55=TRUE,'Raw Data'!AO15-'Raw Data'!AO$9,"") | AP15: =IF(Results!$L$56=TRUE,'Raw Data'!AP15-'Raw Data'!AP$9,"")
B16: 8 | C16: =IF(Results!$L$17=TRUE,'Raw Data'!C16-'Raw Data'!C$9,"") -> 0 | D16: =IF(Results!$L$18=TRUE,'Raw Data'!D16-'Raw Data'!D$9,"") -> 0 | E16: =IF(Results!$L$19=TRUE,'Raw Data'!E16-'Raw Data'!E$9,"") | F16: =IF(Results!$L$20=TRUE,'Raw Data'!F16-'Raw Data'!F$9,"") | G16: =IF(Results!$L$21=TRUE,'Raw Data'!G16-'Raw Data'!G$9,"") | H16: =IF(Results!$L$22=TRUE,'Raw Data'!H16-'Raw Data'!H$9,"") | I16: =IF(Results!$L$23=TRUE,'Raw Data'!I16-'Raw Data'!I$9,"") | J16: =IF(Results!$L$24=TRUE,'Raw Data'!J16-'Raw Data'!J$9,"") | K16: =IF(Results!$L$25=TRUE,'Raw Data'!K16-'Raw Data'!K$9,"") | L16: =IF(Results!$L$26=TRUE,'Raw Data'!L16-'Raw Data'!L$9,"") | M16: =IF(Results!$L$27=TRUE,'Raw Data'!M16-'Raw Data'!M$9,"") | N16: =IF(Results!$L$28=TRUE,'Raw Data'!N16-'Raw Data'!N$9,"") | O16: =IF(Results!$L$29=TRUE,'Raw Data'!O16-'Raw Data'!O$9,"") | P16: =IF(Results!$L$30=TRUE,'Raw Data'!P16-'Raw Data'!P$9,"") | Q16: =IF(Results!$L$31=TRUE,'Raw Data'!Q16-'Raw Data'!Q$9,"") | R16: =IF(Results!$L$32=TRUE,'Raw Data'!R16-'Raw Data'!R$9,"") | S16: =IF(Results!$L$33=TRUE,'Raw Data'!S16-'Raw Data'!S$9,"") | T16: =IF(Results!$L$34=TRUE,'Raw Data'!T16-'Raw Data'!T$9,"") | U16: =IF(Results!$L$35=TRUE,'Raw Data'!U16-'Raw Data'!U$9,"") | V16: =IF(Results!$L$36=TRUE,'Raw Data'!V16-'Raw Data'!V$9,"") | W16: =IF(Results!$L$37=TRUE,'Raw Data'!W16-'Raw Data'!W$9,"") | X16: =IF(Results!$L$38=TRUE,'Raw Data'!X16-'Raw Data'!X$9,"") | Y16: =IF(Results!$L$39=TRUE,'Raw Data'!Y16-'Raw Data'!Y$9,"") | Z16: =IF(Results!$L$40=TRUE,'Raw Data'!Z16-'Raw Data'!Z$9,"") | AA16: =IF(Results!$L$41=TRUE,'Raw Data'!AA16-'Raw Data'!AA$9,"") | AB16: =IF(Results!$L$42=TRUE,'Raw Data'!AB16-'Raw Data'!AB$9,"") | AC16: =IF(Results!$L$43=TRUE,'Raw Data'!AC16-'Raw Data'!AC$9,"") | AD16: =IF(Results!$L$44=TRUE,'Raw Data'!AD16-'Raw Data'!AD$9,"") | AE16: =IF(Results!$L$45=TRUE,'Raw Data'!AE16-'Raw Data'!AE$9,"") | AF16: =IF(Results!$L$46=TRUE,'Raw Data'!AF16-'Raw Data'!AF$9,"") | AG16: =IF(Results!$L$47=TRUE,'Raw Data'!AG16-'Raw Data'!AG$9,"") | AH16: =IF(Results!$L$48=TRUE,'Raw Data'!AH16-'Raw Data'!AH$9,"") | AI16: =IF(Results!$L$49=TRUE,'Raw Data'!AI16-'Raw Data'!AI$9,"") | AJ16: =IF(Results!$L$50=TRUE,'Raw Data'!AJ16-'Raw Data'!AJ$9,"") | AK16: =IF(Results!$L$51=TRUE,'Raw Data'!AK16-'Raw Data'!AK$9,"") | AL16: =IF(Results!$L$52=TRUE,'Raw Data'!AL16-'Raw Data'!AL$9,"") | AM16: =IF(Results!$L$53=TRUE,'Raw Data'!AM16-'Raw Data'!AM$9,"") | AN16: =IF(Results!$L$54=TRUE,'Raw Data'!AN16-'Raw Data'!AN$9,"") | AO16: =IF(Results!$L$55=TRUE,'Raw Data'!AO16-'Raw Data'!AO$9,"") | AP16: =IF(Results!$L$56=TRUE,'Raw Data'!AP16-'Raw Data'!AP$9,"")
B17: 9 | C17: =IF(Results!$L$17=TRUE,'Raw Data'!C17-'Raw Data'!C$9,"") -> 0 | D17: =IF(Results!$L$18=TRUE,'Raw Data'!D17-'Raw Data'!D$9,"") -> 0 | E17: =IF(Results!$L$19=TRUE,'Raw Data'!E17-'Raw Data'!E$9,"") | F17: =IF(Results!$L$20=TRUE,'Raw Data'!F17-'Raw Data'!F$9,"") | G17: =IF(Results!$L$21=TRUE,'Raw Data'!G17-'Raw Data'!G$9,"") | H17: =IF(Results!$L$22=TRUE,'Raw Data'!H17-'Raw Data'!H$9,"") | I17: =IF(Results!$L$23=TRUE,'Raw Data'!I17-'Raw Data'!I$9,"") | J17: =IF(Results!$L$24=TRUE,'Raw Data'!J17-'Raw Data'!J$9,"") | K17: =IF(Results!$L$25=TRUE,'Raw Data'!K17-'Raw Data'!K$9,"") | L17: =IF(Results!$L$26=TRUE,'Raw Data'!L17-'Raw Data'!L$9,"") | M17: =IF(Results!$L$27=TRUE,'Raw Data'!M17-'Raw Data'!M$9,"") | N17: =IF(Results!$L$28=TRUE,'Raw Data'!N17-'Raw Data'!N$9,"") | O17: =IF(Results!$L$29=TRUE,'Raw Data'!O17-'Raw Data'!O$9,"") | P17: =IF(Results!$L$30=TRUE,'Raw Data'!P17-'Raw Data'!P$9,"") | Q17: =IF(Results!$L$31=TRUE,'Raw Data'!Q17-'Raw Data'!Q$9,"") | R17: =IF(Results!$L$32=TRUE,'Raw Data'!R17-'Raw Data'!R$9,"") | S17: =IF(Results!$L$33=TRUE,'Raw Data'!S17-'Raw Data'!S$9,"") | T17: =IF(Results!$L$34=TRUE,'Raw Data'!T17-'Raw Data'!T$9,"") | U17: =IF(Results!$L$35=TRUE,'Raw Data'!U17-'Raw Data'!U$9,"") | V17: =IF(Results!$L$36=TRUE,'Raw Data'!V17-'Raw Data'!V$9,"") | W17: =IF(Results!$L$37=TRUE,'Raw Data'!W17-'Raw Data'!W$9,"") | X17: =IF(Results!$L$38=TRUE,'Raw Data'!X17-'Raw Data'!X$9,"") | Y17: =IF(Results!$L$39=TRUE,'Raw Data'!Y17-'Raw Data'!Y$9,"") | Z17: =IF(Results!$L$40=TRUE,'Raw Data'!Z17-'Raw Data'!Z$9,"") | AA17: =IF(Results!$L$41=TRUE,'Raw Data'!AA17-'Raw Data'!AA$9,"") | AB17: =IF(Results!$L$42=TRUE,'Raw Data'!AB17-'Raw Data'!AB$9,"") | AC17: =IF(Results!$L$43=TRUE,'Raw Data'!AC17-'Raw Data'!AC$9,"") | AD17: =IF(Results!$L$44=TRUE,'Raw Data'!AD17-'Raw Data'!AD$9,"") | AE17: =IF(Results!$L$45=TRUE,'Raw Data'!AE17-'Raw Data'!AE$9,"") | AF17: =IF(Results!$L$46=TRUE,'Raw Data'!AF17-'Raw Data'!AF$9,"") | AG17: =IF(Results!$L$47=TRUE,'Raw Data'!AG17-'Raw Data'!AG$9,"") | AH17: =IF(Results!$L$48=TRUE,'Raw Data'!AH17-'Raw Data'!AH$9,"") | AI17: =IF(Results!$L$49=TRUE,'Raw Data'!AI17-'Raw Data'!AI$9,"") | AJ17: =IF(Results!$L$50=TRUE,'Raw Data'!AJ17-'Raw Data'!AJ$9,"") | AK17: =IF(Results!$L$51=TRUE,'Raw Data'!AK17-'Raw Data'!AK$9,"") | AL17: =IF(Results!$L$52=TRUE,'Raw Data'!AL17-'Raw Data'!AL$9,"") | AM17: =IF(Results!$L$53=TRUE,'Raw Data'!AM17-'Raw Data'!AM$9,"") | AN17: =IF(Results!$L$54=TRUE,'Raw Data'!AN17-'Raw Data'!AN$9,"") | AO17: =IF(Results!$L$55=TRUE,'Raw Data'!AO17-'Raw Data'!AO$9,"") | AP17: =IF(Results!$L$56=TRUE,'Raw Data'!AP17-'Raw Data'!AP$9,"")
B18: 10 | C18: =IF(Results!$L$17=TRUE,'Raw Data'!C18-'Raw Data'!C$9,"") -> 0 | D18: =IF(Results!$L$18=TRUE,'Raw Data'!D18-'Raw Data'!D$9,"") -> 0 | E18: =IF(Results!$L$19=TRUE,'Raw Data'!E18-'Raw Data'!E$9,"") | F18: =IF(Results!$L$20=TRUE,'Raw Data'!F18-'Raw Data'!F$9,"") | G18: =IF(Results!$L$21=TRUE,'Raw Data'!G18-'Raw Data'!G$9,"") | H18: =IF(Results!$L$22=TRUE,'Raw Data'!H18-'Raw Data'!H$9,"") | I18: =IF(Results!$L$23=TRUE,'Raw Data'!I18-'Raw Data'!I$9,"") | J18: =IF(Results!$L$24=TRUE,'Raw Data'!J18-'Raw Data'!J$9,"") | K18: =IF(Results!$L$25=TRUE,'Raw Data'!K18-'Raw Data'!K$9,"") | L18: =IF(Results!$L$26=TRUE,'Raw Data'!L18-'Raw Data'!L$9,"") | M18: =IF(Results!$L$27=TRUE,'Raw Data'!M18-'Raw Data'!M$9,"") | N18: =IF(Results!$L$28=TRUE,'Raw Data'!N18-'Raw Data'!N$9,"") | O18: =IF(Results!$L$29=TRUE,'Raw Data'!O18-'Raw Data'!O$9,"") | P18: =IF(Results!$L$30=TRUE,'Raw Data'!P18-'Raw Data'!P$9,"") | Q18: =IF(Results!$L$31=TRUE,'Raw Data'!Q18-'Raw Data'!Q$9,"") | R18: =IF(Results!$L$32=TRUE,'Raw Data'!R18-'Raw Data'!R$9,"") | S18: =IF(Results!$L$33=TRUE,'Raw Data'!S18-'Raw Data'!S$9,"") | T18: =IF(Results!$L$34=TRUE,'Raw Data'!T18-'Raw Data'!T$9,"") | U18: =IF(Results!$L$35=TRUE,'Raw Data'!U18-'Raw Data'!U$9,"") | V18: =IF(Results!$L$36=TRUE,'Raw Data'!V18-'Raw Data'!V$9,"") | W18: =IF(Results!$L$37=TRUE,'Raw Data'!W18-'Raw Data'!W$9,"") | X18: =IF(Results!$L$38=TRUE,'Raw Data'!X18-'Raw Data'!X$9,"") | Y18: =IF(Results!$L$39=TRUE,'Raw Data'!Y18-'Raw Data'!Y$9,"") | Z18: =IF(Results!$L$40=TRUE,'Raw Data'!Z18-'Raw Data'!Z$9,"") | AA18: =IF(Results!$L$41=TRUE,'Raw Data'!AA18-'Raw Data'!AA$9,"") | AB18: =IF(Results!$L$42=TRUE,'Raw Data'!AB18-'Raw Data'!AB$9,"") | AC18: =IF(Results!$L$43=TRUE,'Raw Data'!AC18-'Raw Data'!AC$9,"") | AD18: =IF(Results!$L$44=TRUE,'Raw Data'!AD18-'Raw Data'!AD$9,"") | AE18: =IF(Results!$L$45=TRUE,'Raw Data'!AE18-'Raw Data'!AE$9,"") | AF18: =IF(Results!$L$46=TRUE,'Raw Data'!AF18-'Raw Data'!AF$9,"") | AG18: =IF(Results!$L$47=TRUE,'Raw Data'!AG18-'Raw Data'!AG$9,"") | AH18: =IF(Results!$L$48=TRUE,'Raw Data'!AH18-'Raw Data'!AH$9,"") | AI18: =IF(Results!$L$49=TRUE,'Raw Data'!AI18-'Raw Data'!AI$9,"") | AJ18: =IF(Results!$L$50=TRUE,'Raw Data'!AJ18-'Raw Data'!AJ$9,"") | AK18: =IF(Results!$L$51=TRUE,'Raw Data'!AK18-'Raw Data'!AK$9,"") | AL18: =IF(Results!$L$52=TRUE,'Raw Data'!AL18-'Raw Data'!AL$9,"") | AM18: =IF(Results!$L$53=TRUE,'Raw Data'!AM18-'Raw Data'!AM$9,"") | AN18: =IF(Results!$L$54=TRUE,'Raw Data'!AN18-'Raw Data'!AN$9,"") | AO18: =IF(Results!$L$55=TRUE,'Raw Data'!AO18-'Raw Data'!AO$9,"") | AP18: =IF(Results!$L$56=TRUE,'Raw Data'!AP18-'Raw Data'!AP$9,"")
B19: 11 | C19: =IF(Results!$L$17=TRUE,'Raw Data'!C19-'Raw Data'!C$9,"") -> 0 | D19: =IF(Results!$L$18=TRUE,'Raw Data'!D19-'Raw Data'!D$9,"") -> 0 | E19: =IF(Results!$L$19=TRUE,'Raw Data'!E19-'Raw Data'!E$9,"") | F19: =IF(Results!$L$20=TRUE,'Raw Data'!F19-'Raw Data'!F$9,"") | G19: =IF(Results!$L$21=TRUE,'Raw Data'!G19-'Raw Data'!G$9,"") | H19: =IF(Results!$L$22=TRUE,'Raw Data'!H19-'Raw Data'!H$9,"") | I19: =IF(Results!$L$23=TRUE,'Raw Data'!I19-'Raw Data'!I$9,"") | J19: =IF(Results!$L$24=TRUE,'Raw Data'!J19-'Raw Data'!J$9,"") | K19: =IF(Results!$L$25=TRUE,'Raw Data'!K19-'Raw Data'!K$9,"") | L19: =IF(Results!$L$26=TRUE,'Raw Data'!L19-'Raw Data'!L$9,"") | M19: =IF(Results!$L$27=TRUE,'Raw Data'!M19-'Raw Data'!M$9,"") | N19: =IF(Results!$L$28=TRUE,'Raw Data'!N19-'Raw Data'!N$9,"") | O19: =IF(Results!$L$29=TRUE,'Raw Data'!O19-'Raw Data'!O$9,"") | P19: =IF(Results!$L$30=TRUE,'Raw Data'!P19-'Raw Data'!P$9,"") | Q19: =IF(Results!$L$31=TRUE,'Raw Data'!Q19-'Raw Data'!Q$9,"") | R19: =IF(Results!$L$32=TRUE,'Raw Data'!R19-'Raw Data'!R$9,"") | S19: =IF(Results!$L$33=TRUE,'Raw Data'!S19-'Raw Data'!S$9,"") | T19: =IF(Results!$L$34=TRUE,'Raw Data'!T19-'Raw Data'!T$9,"") | U19: =IF(Results!$L$35=TRUE,'Raw Data'!U19-'Raw Data'!U$9,"") | V19: =IF(Results!$L$36=TRUE,'Raw Data'!V19-'Raw Data'!V$9,"") | W19: =IF(Results!$L$37=TRUE,'Raw Data'!W19-'Raw Data'!W$9,"") | X19: =IF(Results!$L$38=TRUE,'Raw Data'!X19-'Raw Data'!X$9,"") | Y19: =IF(Results!$L$39=TRUE,'Raw Data'!Y19-'Raw Data'!Y$9,"") | Z19: =IF(Results!$L$40=TRUE,'Raw Data'!Z19-'Raw Data'!Z$9,"") | AA19: =IF(Results!$L$41=TRUE,'Raw Data'!AA19-'Raw Data'!AA$9,"") | AB19: =IF(Results!$L$42=TRUE,'Raw Data'!AB19-'Raw Data'!AB$9,"") | AC19: =IF(Results!$L$43=TRUE,'Raw Data'!AC19-'Raw Data'!AC$9,"") | AD19: =IF(Results!$L$44=TRUE,'Raw Data'!AD19-'Raw Data'!AD$9,"") | AE19: =IF(Results!$L$45=TRUE,'Raw Data'!AE19-'Raw Data'!AE$9,"") | AF19: =IF(Results!$L$46=TRUE,'Raw Data'!AF19-'Raw Data'!AF$9,"") | AG19: =IF(Results!$L$47=TRUE,'Raw Data'!AG19-'Raw Data'!AG$9,"") | AH19: =IF(Results!$L$48=TRUE,'Raw Data'!AH19-'Raw Data'!AH$9,"") | AI19: =IF(Results!$L$49=TRUE,'Raw Data'!AI19-'Raw Data'!AI$9,"") | AJ19: =IF(Results!$L$50=TRUE,'Raw Data'!AJ19-'Raw Data'!AJ$9,"") | AK19: =IF(Results!$L$51=TRUE,'Raw Data'!AK19-'Raw Data'!AK$9,"") | AL19: =IF(Results!$L$52=TRUE,'Raw Data'!AL19-'Raw Data'!AL$9,"") | AM19: =IF(Results!$L$53=TRUE,'Raw Data'!AM19-'Raw Data'!AM$9,"") | AN19: =IF(Results!$L$54=TRUE,'Raw Data'!AN19-'Raw Data'!AN$9,"") | AO19: =IF(Results!$L$55=TRUE,'Raw Data'!AO19-'Raw Data'!AO$9,"") | AP19: =IF(Results!$L$56=TRUE,'Raw Data'!AP19-'Raw Data'!AP$9,"")
B20: 12 | C20: =IF(Results!$L$17=TRUE,'Raw Data'!C20-'Raw Data'!C$9,"") -> 0 | D20: =IF(Results!$L$18=TRUE,'Raw Data'!D20-'Raw Data'!D$9,"") -> 0 | E20: =IF(Results!$L$19=TRUE,'Raw Data'!E20-'Raw Data'!E$9,"") | F20: =IF(Results!$L$20=TRUE,'Raw Data'!F20-'Raw Data'!F$9,"") | G20: =IF(Results!$L$21=TRUE,'Raw Data'!G20-'Raw Data'!G$9,"") | H20: =IF(Results!$L$22=TRUE,'Raw Data'!H20-'Raw Data'!H$9,"") | I20: =IF(Results!$L$23=TRUE,'Raw Data'!I20-'Raw Data'!I$9,"") | J20: =IF(Results!$L$24=TRUE,'Raw Data'!J20-'Raw Data'!J$9,"") | K20: =IF(Results!$L$25=TRUE,'Raw Data'!K20-'Raw Data'!K$9,"") | L20: =IF(Results!$L$26=TRUE,'Raw Data'!L20-'Raw Data'!L$9,"") | M20: =IF(Results!$L$27=TRUE,'Raw Data'!M20-'Raw Data'!M$9,"") | N20: =IF(Results!$L$28=TRUE,'Raw Data'!N20-'Raw Data'!N$9,"") | O20: =IF(Results!$L$29=TRUE,'Raw Data'!O20-'Raw Data'!O$9,"") | P20: =IF(Results!$L$30=TRUE,'Raw Data'!P20-'Raw Data'!P$9,"") | Q20: =IF(Results!$L$31=TRUE,'Raw Data'!Q20-'Raw Data'!Q$9,"") | R20: =IF(Results!$L$32=TRUE,'Raw Data'!R20-'Raw Data'!R$9,"") | S20: =IF(Results!$L$33=TRUE,'Raw Data'!S20-'Raw Data'!S$9,"") | T20: =IF(Results!$L$34=TRUE,'Raw Data'!T20-'Raw Data'!T$9,"") | U20: =IF(Results!$L$35=TRUE,'Raw Data'!U20-'Raw Data'!U$9,"") | V20: =IF(Results!$L$36=TRUE,'Raw Data'!V20-'Raw Data'!V$9,"") | W20: =IF(Results!$L$37=TRUE,'Raw Data'!W20-'Raw Data'!W$9,"") | X20: =IF(Results!$L$38=TRUE,'Raw Data'!X20-'Raw Data'!X$9,"") | Y20: =IF(Results!$L$39=TRUE,'Raw Data'!Y20-'Raw Data'!Y$9,"") | Z20: =IF(Results!$L$40=TRUE,'Raw Data'!Z20-'Raw Data'!Z$9,"") | AA20: =IF(Results!$L$41=TRUE,'Raw Data'!AA20-'Raw Data'!AA$9,"") | AB20: =IF(Results!$L$42=TRUE,'Raw Data'!AB20-'Raw Data'!AB$9,"") | AC20: =IF(Results!$L$43=TRUE,'Raw Data'!AC20-'Raw Data'!AC$9,"") | AD20: =IF(Results!$L$44=TRUE,'Raw Data'!AD20-'Raw Data'!AD$9,"") | AE20: =IF(Results!$L$45=TRUE,'Raw Data'!AE20-'Raw Data'!AE$9,"") | AF20: =IF(Results!$L$46=TRUE,'Raw Data'!AF20-'Raw Data'!AF$9,"") | AG20: =IF(Results!$L$47=TRUE,'Raw Data'!AG20-'Raw Data'!AG$9,"") | AH20: =IF(Results!$L$48=TRUE,'Raw Data'!AH20-'Raw Data'!AH$9,"") | AI20: =IF(Results!$L$49=TRUE,'Raw Data'!AI20-'Raw Data'!AI$9,"") | AJ20: =IF(Results!$L$50=TRUE,'Raw Data'!AJ20-'Raw Data'!AJ$9,"") | AK20: =IF(Results!$L$51=TRUE,'Raw Data'!AK20-'Raw Data'!AK$9,"") | AL20: =IF(Results!$L$52=TRUE,'Raw Data'!AL20-'Raw Data'!AL$9,"") | AM20: =IF(Results!$L$53=TRUE,'Raw Data'!AM20-'Raw Data'!AM$9,"") | AN20: =IF(Results!$L$54=TRUE,'Raw Data'!AN20-'Raw Data'!AN$9,"") | AO20: =IF(Results!$L$55=TRUE,'Raw Data'!AO20-'Raw Data'!AO$9,"") | AP20: =IF(Results!$L$56=TRUE,'Raw Data'!AP20-'Raw Data'!AP$9,"")
... B287: 279 | C287: =IF(Results!$L$17=TRUE,'Raw Data'!C287-'Raw Data'!C$9,"") -> 0 | D287: =IF(Results!$L$18=TRUE,'Raw Data'!D287-'Raw Data'!D$9,"") -> 0 | E287: =IF(Results!$L$19=TRUE,'Raw Data'!E287-'Raw Data'!E$9,"") | F287: =IF(Results!$L$20=TRUE,'Raw Data'!F287-'Raw Data'!F$9,"") | G287: =IF(Results!$L$21=TRUE,'Raw Data'!G287-'Raw Data'!G$9,"") | H287: =IF(Results!$L$22=TRUE,'Raw Data'!H287-'Raw Data'!H$9,"") | I287: =IF(Results!$L$23=TRUE,'Raw Data'!I287-'Raw Data'!I$9,"") | J287: =IF(Results!$L$24=TRUE,'Raw Data'!J287-'Raw Data'!J$9,"") | K287: =IF(Results!$L$25=TRUE,'Raw Data'!K287-'Raw Data'!K$9,"") | L287: =IF(Results!$L$26=TRUE,'Raw Data'!L287-'Raw Data'!L$9,"") | M287: =IF(Results!$L$27=TRUE,'Raw Data'!M287-'Raw Data'!M$9,"") | N287: =IF(Results!$L$28=TRUE,'Raw Data'!N287-'Raw Data'!N$9,"") | O287: =IF(Results!$L$29=TRUE,'Raw Data'!O287-'Raw Data'!O$9,"") | P287: =IF(Results!$L$30=TRUE,'Raw Data'!P287-'Raw Data'!P$9,"") | Q287: =IF(Results!$L$31=TRUE,'Raw Data'!Q287-'Raw Data'!Q$9,"") | R287: =IF(Results!$L$32=TRUE,'Raw Data'!R287-'Raw Data'!R$9,"") | S287: =IF(Results!$L$33=TRUE,'Raw Data'!S287-'Raw Data'!S$9,"") | T287: =IF(Results!$L$34=TRUE,'Raw Data'!T287-'Raw Data'!T$9,"") | U287: =IF(Results!$L$35=TRUE,'Raw Data'!U287-'Raw Data'!U$9,"") | V287: =IF(Results!$L$36=TRUE,'Raw Data'!V287-'Raw Data'!V$9,"") | W287: =IF(Results!$L$37=TRUE,'Raw Data'!W287-'Raw Data'!W$9,"") | X287: =IF(Results!$L$38=TRUE,'Raw Data'!X287-'Raw Data'!X$9,"") | Y287: =IF(Results!$L$39=TRUE,'Raw Data'!Y287-'Raw Data'!Y$9,"") | Z287: =IF(Results!$L$40=TRUE,'Raw Data'!Z287-'Raw Data'!Z$9,"") | AA287: =IF(Results!$L$41=TRUE,'Raw Data'!AA287-'Raw Data'!AA$9,"") | AB287: =IF(Results!$L$42=TRUE,'Raw Data'!AB287-'Raw Data'!AB$9,"") | AC287: =IF(Results!$L$43=TRUE,'Raw Data'!AC287-'Raw Data'!AC$9,"") | AD287: =IF(Results!$L$44=TRUE,'Raw Data'!AD287-'Raw Data'!AD$9,"") | AE287: =IF(Results!$L$45=TRUE,'Raw Data'!AE287-'Raw Data'!AE$9,"") | AF287: =IF(Results!$L$46=TRUE,'Raw Data'!AF287-'Raw Data'!AF$9,"") | AG287: =IF(Results!$L$47=TRUE,'Raw Data'!AG287-'Raw Data'!AG$9,"") | AH287: =IF(Results!$L$48=TRUE,'Raw Data'!AH287-'Raw Data'!AH$9,"") | AI287: =IF(Results!$L$49=TRUE,'Raw Data'!AI287-'Raw Data'!AI$9,"") | AJ287: =IF(Results!$L$50=TRUE,'Raw Data'!AJ287-'Raw Data'!AJ$9,"") | AK287: =IF(Results!$L$51=TRUE,'Raw Data'!AK287-'Raw Data'!AK$9,"") | AL287: =IF(Results!$L$52=TRUE,'Raw Data'!AL287-'Raw Data'!AL$9,"") | AM287: =IF(Results!$L$53=TRUE,'Raw Data'!AM287-'Raw Data'!AM$9,"") | AN287: =IF(Results!$L$54=TRUE,'Raw Data'!AN287-'Raw Data'!AN$9,"") | AO287: =IF(Results!$L$55=TRUE,'Raw Data'!AO287-'Raw Data'!AO$9,"") | AP287: =IF(Results!$L$56=TRUE,'Raw Data'!AP287-'Raw Data'!AP$9,"")
