Workbook

Sheet Results
C16: Test | D16: Instrument Number | E16: Time | F16: Date | G16: Cassette Identifier Code | H16: Sample ID | I16: Result | J16: Method | K16: Version | L16: Lot Code | M16: View
C17: 1 | D17: =IF(ISBLANK('Raw Data'!C$9),"",'Raw Data'!C$9) | E17: =IF(ISBLANK('Raw Data'!C$1),"",'Raw Data'!C$1) | F17: =IF(ISBLANK('Raw Data'!C$2),"",'Raw Data'!C$2) | G17: =IF(ISBLANK('Raw Data'!C$3),"",'Raw Data'!C$3) | H17: =IF(ISBLANK('Raw Data'!C$4),"",'Raw Data'!C$4) | I17: =IF(ISBLANK('Raw Data'!C$5),"",'Raw Data'!C$5) | J17: =IF(ISBLANK('Raw Data'!C$6),"",'Raw Data'!C$6) | K17: =IF(ISBLANK('Raw Data'!C$7),"",'Raw Data'!C$7) | L17: =IF(ISBLANK('Raw Data'!C$8),"",'Raw Data'!C$8) | M17: No
C18: 2 | D18: =IF(ISBLANK('Raw Data'!D$9),"",'Raw Data'!D$9) | E18: =IF(ISBLANK('Raw Data'!D$1),"",'Raw Data'!D$1) | F18: =IF(ISBLANK('Raw Data'!D$2),"",'Raw Data'!D$2) | G18: =IF(ISBLANK('Raw Data'!D$3),"",'Raw Data'!D$3) | H18: =IF(ISBLANK('Raw Data'!D$4),"",'Raw Data'!D$4) | I18: =IF(ISBLANK('Raw Data'!D$5),"",'Raw Data'!D$5) | J18: =IF(ISBLANK('Raw Data'!D$6),"",'Raw Data'!D$6) | K18: =IF(ISBLANK('Raw Data'!D$7),"",'Raw Data'!D$7) | L18: =IF(ISBLANK('Raw Data'!D$8),"",'Raw Data'!D$8)
C19: 3 | D19: =IF(ISBLANK('Raw Data'!E$9),"",'Raw Data'!E$9) | E19: =IF(ISBLANK('Raw Data'!E$1),"",'Raw Data'!E$1) | F19: =IF(ISBLANK('Raw Data'!E$2),"",'Raw Data'!E$2) | G19: =IF(ISBLANK('Raw Data'!E$3),"",'Raw Data'!E$3) | H19: =IF(ISBLANK('Raw Data'!E$4),"",'Raw Data'!E$4) | I19: =IF(ISBLANK('Raw Data'!E$5),"",'Raw Data'!E$5) | J19: =IF(ISBLANK('Raw Data'!E$6),"",'Raw Data'!E$6) | K19: =IF(ISBLANK('Raw Data'!E$7),"",'Raw Data'!E$7) | L19: =IF(ISBLANK('Raw Data'!E$8),"",'Raw Data'!E$8)
C20: 4 | D20: =IF(ISBLANK('Raw Data'!F$9),"",'Raw Data'!F$9) | E20: =IF(ISBLANK('Raw Data'!F$1),"",'Raw Data'!F$1) | F20: =IF(ISBLANK('Raw Data'!F$2),"",'Raw Data'!F$2) | G20: =IF(ISBLANK('Raw Data'!F$3),"",'Raw Data'!F$3) | H20: =IF(ISBLANK('Raw Data'!F$4),"",'Raw Data'!F$4) | I20: =IF(ISBLANK('Raw Data'!F$5),"",'Raw Data'!F$5) | J20: =IF(ISBLANK('Raw Data'!F$6),"",'Raw Data'!F$6) | K20: =IF(ISBLANK('Raw Data'!F$7),"",'Raw Data'!F$7) | L20: =IF(ISBLANK('Raw Data'!F$8),"",'Raw Data'!F$8)
C21: 5 | D21: =IF(ISBLANK('Raw Data'!G$9),"",'Raw Data'!G$9) | E21: =IF(ISBLANK('Raw Data'!G$1),"",'Raw Data'!G$1) | F21: =IF(ISBLANK('Raw Data'!G$2),"",'Raw Data'!G$2) | G21: =IF(ISBLANK('Raw Data'!G$3),"",'Raw Data'!G$3) | H21: =IF(ISBLANK('Raw Data'!G$4),"",'Raw Data'!G$4) | I21: =IF(ISBLANK('Raw Data'!G$5),"",'Raw Data'!G$5) | J21: =IF(ISBLANK('Raw Data'!G$6),"",'Raw Data'!G$6) | K21: =IF(ISBLANK('Raw Data'!G$7),"",'Raw Data'!G$7) | L21: =IF(ISBLANK('Raw Data'!G$8),"",'Raw Data'!G$8)
C22: 6 | D22: =IF(ISBLANK('Raw Data'!H$9),"",'Raw Data'!H$9) | E22: =IF(ISBLANK('Raw Data'!H$1),"",'Raw Data'!H$1) | F22: =IF(ISBLANK('Raw Data'!H$2),"",'Raw Data'!H$2) | G22: =IF(ISBLANK('Raw Data'!H$3),"",'Raw Data'!H$3) | H22: =IF(ISBLANK('Raw Data'!H$4),"",'Raw Data'!H$4) | I22: =IF(ISBLANK('Raw Data'!H$5),"",'Raw Data'!H$5) | J22: =IF(ISBLANK('Raw Data'!H$6),"",'Raw Data'!H$6) | K22: =IF(ISBLANK('Raw Data'!H$7),"",'Raw Data'!H$7) | L22: =IF(ISBLANK('Raw Data'!H$8),"",'Raw Data'!H$8)
C23: 7 | D23: =IF(ISBLANK('Raw Data'!I$9),"",'Raw Data'!I$9) | E23: =IF(ISBLANK('Raw Data'!I$1),"",'Raw Data'!I$1) | F23: =IF(ISBLANK('Raw Data'!I$2),"",'Raw Data'!I$2) | G23: =IF(ISBLANK('Raw Data'!I$3),"",'Raw Data'!I$3) | H23: =IF(ISBLANK('Raw Data'!I$4),"",'Raw Data'!I$4) | I23: =IF(ISBLANK('Raw Data'!I$5),"",'Raw Data'!I$5) | J23: =IF(ISBLANK('Raw Data'!I$6),"",'Raw Data'!I$6) | K23: =IF(ISBLANK('Raw Data'!I$7),"",'Raw Data'!I$7) | L23: =IF(ISBLANK('Raw Data'!I$8),"",'Raw Data'!I$8)
C24: 8 | D24: =IF(ISBLANK('Raw Data'!J$9),"",'Raw Data'!J$9) | E24: =IF(ISBLANK('Raw Data'!J$1),"",'Raw Data'!J$1) | F24: =IF(ISBLANK('Raw Data'!J$2),"",'Raw Data'!J$2) | G24: =IF(ISBLANK('Raw Data'!J$3),"",'Raw Data'!J$3) | H24: =IF(ISBLANK('Raw Data'!J$4),"",'Raw Data'!J$4) | I24: =IF(ISBLANK('Raw Data'!J$5),"",'Raw Data'!J$5) | J24: =IF(ISBLANK('Raw Data'!J$6),"",'Raw Data'!J$6) | K24: =IF(ISBLANK('Raw Data'!J$7),"",'Raw Data'!J$7) | L24: =IF(ISBLANK('Raw Data'!J$8),"",'Raw Data'!J$8)
C25: 9 | D25: =IF(ISBLANK('Raw Data'!K$9),"",'Raw Data'!K$9) | E25: =IF(ISBLANK('Raw Data'!K$1),"",'Raw Data'!K$1) | F25: =IF(ISBLANK('Raw Data'!K$2),"",'Raw Data'!K$2) | G25: =IF(ISBLANK('Raw Data'!K$3),"",'Raw Data'!K$3) | H25: =IF(ISBLANK('Raw Data'!K$4),"",'Raw Data'!K$4) | I25: =IF(ISBLANK('Raw Data'!K$5),"",'Raw Data'!K$5) | J25: =IF(ISBLANK('Raw Data'!K$6),"",'Raw Data'!K$6) | K25: =IF(ISBLANK('Raw Data'!K$7),"",'Raw Data'!K$7) | L25: =IF(ISBLANK('Raw Data'!K$8),"",'Raw Data'!K$8)
C26: 10 | D26: =IF(ISBLANK('Raw Data'!L$9),"",'Raw Data'!L$9) | E26: =IF(ISBLANK('Raw Data'!L$1),"",'Raw Data'!L$1) | F26: =IF(ISBLANK('Raw Data'!L$2),"",'Raw Data'!L$2) | G26: =IF(ISBLANK('Raw Data'!L$3),"",'Raw Data'!L$3) | H26: =IF(ISBLANK('Raw Data'!L$4),"",'Raw Data'!L$4) | I26: =IF(ISBLANK('Raw Data'!L$5),"",'Raw Data'!L$5) | J26: =IF(ISBLANK('Raw Data'!L$6),"",'Raw Data'!L$6) | K26: =IF(ISBLANK('Raw Data'!L$7),"",'Raw Data'!L$7) | L26: =IF(ISBLANK('Raw Data'!L$8),"",'Raw Data'!L$8)
C27: 11 | D27: =IF(ISBLANK('Raw Data'!M$9),"",'Raw Data'!M$9) | E27: =IF(ISBLANK('Raw Data'!M$1),"",'Raw Data'!M$1) | F27: =IF(ISBLANK('Raw Data'!M$2),"",'Raw Data'!M$2) | G27: =IF(ISBLANK('Raw Data'!M$3),"",'Raw Data'!M$3) | H27: =IF(ISBLANK('Raw Data'!M$4),"",'Raw Data'!M$4) | I27: =IF(ISBLANK('Raw Data'!M$5),"",'Raw Data'!M$5) | J27: =IF(ISBLANK('Raw Data'!M$6),"",'Raw Data'!M$6) | K27: =IF(ISBLANK('Raw Data'!M$7),"",'Raw Data'!M$7) | L27: =IF(ISBLANK('Raw Data'!M$8),"",'Raw Data'!M$8)
C28: 12 | D28: =IF(ISBLANK('Raw Data'!N$9),"",'Raw Data'!N$9) | E28: =IF(ISBLANK('Raw Data'!N$1),"",'Raw Data'!N$1) | F28: =IF(ISBLANK('Raw Data'!N$2),"",'Raw Data'!N$2) | G28: =IF(ISBLANK('Raw Data'!N$3),"",'Raw Data'!N$3) | H28: =IF(ISBLANK('Raw Data'!N$4),"",'Raw Data'!N$4) | I28: =IF(ISBLANK('Raw Data'!N$5),"",'Raw Data'!N$5) | J28: =IF(ISBLANK('Raw Data'!N$6),"",'Raw Data'!N$6) | K28: =IF(ISBLANK('Raw Data'!N$7),"",'Raw Data'!N$7) | L28: =IF(ISBLANK('Raw Data'!N$8),"",'Raw Data'!N$8)
C29: 13 | D29: =IF(ISBLANK('Raw Data'!O$9),"",'Raw Data'!O$9) | E29: =IF(ISBLANK('Raw Data'!O$1),"",'Raw Data'!O$1) | F29: =IF(ISBLANK('Raw Data'!O$2),"",'Raw Data'!O$2) | G29: =IF(ISBLANK('Raw Data'!O$3),"",'Raw Data'!O$3) | H29: =IF(ISBLANK('Raw Data'!O$4),"",'Raw Data'!O$4) | I29: =IF(ISBLANK('Raw Data'!O$5),"",'Raw Data'!O$5) | J29: =IF(ISBLANK('Raw Data'!O$6),"",'Raw Data'!O$6) | K29: =IF(ISBLANK('Raw Data'!O$7),"",'Raw Data'!O$7) | L29: =IF(ISBLANK('Raw Data'!O$8),"",'Raw Data'!O$8)
C30: 14 | D30: =IF(ISBLANK('Raw Data'!P$9),"",'Raw Data'!P$9) | E30: =IF(ISBLANK('Raw Data'!P$1),"",'Raw Data'!P$1) | F30: =IF(ISBLANK('Raw Data'!P$2),"",'Raw Data'!P$2) | G30: =IF(ISBLANK('Raw Data'!P$3),"",'Raw Data'!P$3) | H30: =IF(ISBLANK('Raw Data'!P$4),"",'Raw Data'!P$4) | I30: =IF(ISBLANK('Raw Data'!P$5),"",'Raw Data'!P$5) | J30: =IF(ISBLANK('Raw Data'!P$6),"",'Raw Data'!P$6) | K30: =IF(ISBLANK('Raw Data'!P$7),"",'Raw Data'!P$7) | L30: =IF(ISBLANK('Raw Data'!P$8),"",'Raw Data'!P$8)
C31: 15 | D31: =IF(ISBLANK('Raw Data'!Q$9),"",'Raw Data'!Q$9) | E31: =IF(ISBLANK('Raw Data'!Q$1),"",'Raw Data'!Q$1) | F31: =IF(ISBLANK('Raw Data'!Q$2),"",'Raw Data'!Q$2) | G31: =IF(ISBLANK('Raw Data'!Q$3),"",'Raw Data'!Q$3) | H31: =IF(ISBLANK('Raw Data'!Q$4),"",'Raw Data'!Q$4) | I31: =IF(ISBLANK('Raw Data'!Q$5),"",'Raw Data'!Q$5) | J31: =IF(ISBLANK('Raw Data'!Q$6),"",'Raw Data'!Q$6) | K31: =IF(ISBLANK('Raw Data'!Q$7),"",'Raw Data'!Q$7) | L31: =IF(ISBLANK('Raw Data'!Q$8),"",'Raw Data'!Q$8)
C32: 16 | D32: =IF(ISBLANK('Raw Data'!R$9),"",'Raw Data'!R$9) | E32: =IF(ISBLANK('Raw Data'!R$1),"",'Raw Data'!R$1) | F32: =IF(ISBLANK('Raw Data'!R$2),"",'Raw Data'!R$2) | G32: =IF(ISBLANK('Raw Data'!R$3),"",'Raw Data'!R$3) | H32: =IF(ISBLANK('Raw Data'!R$4),"",'Raw Data'!R$4) | I32: =IF(ISBLANK('Raw Data'!R$5),"",'Raw Data'!R$5) | J32: =IF(ISBLANK('Raw Data'!R$6),"",'Raw Data'!R$6) | K32: =IF(ISBLANK('Raw Data'!R$7),"",'Raw Data'!R$7) | L32: =IF(ISBLANK('Raw Data'!R$8),"",'Raw Data'!R$8)
C33: 17 | D33: =IF(ISBLANK('Raw Data'!S$9),"",'Raw Data'!S$9) | E33: =IF(ISBLANK('Raw Data'!S$1),"",'Raw Data'!S$1) | F33: =IF(ISBLANK('Raw Data'!S$2),"",'Raw Data'!S$2) | G33: =IF(ISBLANK('Raw Data'!S$3),"",'Raw Data'!S$3) | H33: =IF(ISBLANK('Raw Data'!S$4),"",'Raw Data'!S$4) | I33: =IF(ISBLANK('Raw Data'!S$5),"",'Raw Data'!S$5) | J33: =IF(ISBLANK('Raw Data'!S$6),"",'Raw Data'!S$6) | K33: =IF(ISBLANK('Raw Data'!S$7),"",'Raw Data'!S$7) | L33: =IF(ISBLANK('Raw Data'!S$8),"",'Raw Data'!S$8)
C34: 18 | D34: =IF(ISBLANK('Raw Data'!T$9),"",'Raw Data'!T$9) | E34: =IF(ISBLANK('Raw Data'!T$1),"",'Raw Data'!T$1) | F34: =IF(ISBLANK('Raw Data'!T$2),"",'Raw Data'!T$2) | G34: =IF(ISBLANK('Raw Data'!T$3),"",'Raw Data'!T$3) | H34: =IF(ISBLANK('Raw Data'!T$4),"",'Raw Data'!T$4) | I34: =IF(ISBLANK('Raw Data'!T$5),"",'Raw Data'!T$5) | J34: =IF(ISBLANK('Raw Data'!T$6),"",'Raw Data'!T$6) | K34: =IF(ISBLANK('Raw Data'!T$7),"",'Raw Data'!T$7) | L34: =IF(ISBLANK('Raw Data'!T$8),"",'Raw Data'!T$8)
C35: 19 | D35: =IF(ISBLANK('Raw Data'!U$9),"",'Raw Data'!U$9) | E35: =IF(ISBLANK('Raw Data'!U$1),"",'Raw Data'!U$1) | F35: =IF(ISBLANK('Raw Data'!U$2),"",'Raw Data'!U$2) | G35: =IF(ISBLANK('Raw Data'!U$3),"",'Raw Data'!U$3) | H35: =IF(ISBLANK('Raw Data'!U$4),"",'Raw Data'!U$4) | I35: =IF(ISBLANK('Raw Data'!U$5),"",'Raw Data'!U$5) | J35: =IF(ISBLANK('Raw Data'!U$6),"",'Raw Data'!U$6) | K35: =IF(ISBLANK('Raw Data'!U$7),"",'Raw Data'!U$7) | L35: =IF(ISBLANK('Raw Data'!U$8),"",'Raw Data'!U$8)
C36: 20 | D36: =IF(ISBLANK('Raw Data'!V$9),"",'Raw Data'!V$9) | E36: =IF(ISBLANK('Raw Data'!V$1),"",'Raw Data'!V$1) | F36: =IF(ISBLANK('Raw Data'!V$2),"",'Raw Data'!V$2) | G36: =IF(ISBLANK('Raw Data'!V$3),"",'Raw Data'!V$3) | H36: =IF(ISBLANK('Raw Data'!V$4),"",'Raw Data'!V$4) | I36: =IF(ISBLANK('Raw Data'!V$5),"",'Raw Data'!V$5) | J36: =IF(ISBLANK('Raw Data'!V$6),"",'Raw Data'!V$6) | K36: =IF(ISBLANK('Raw Data'!V$7),"",'Raw Data'!V$7) | L36: =IF(ISBLANK('Raw Data'!V$8),"",'Raw Data'!V$8)
C37: 21 | D37: =IF(ISBLANK('Raw Data'!W$9),"",'Raw Data'!W$9) | E37: =IF(ISBLANK('Raw Data'!W$1),"",'Raw Data'!W$1) | F37: =IF(ISBLANK('Raw Data'!W$2),"",'Raw Data'!W$2) | G37: =IF(ISBLANK('Raw Data'!W$3),"",'Raw Data'!W$3) | H37: =IF(ISBLANK('Raw Data'!W$4),"",'Raw Data'!W$4) | I37: =IF(ISBLANK('Raw Data'!W$5),"",'Raw Data'!W$5) | J37: =IF(ISBLANK('Raw Data'!W$6),"",'Raw Data'!W$6) | K37: =IF(ISBLANK('Raw Data'!W$7),"",'Raw Data'!W$7) | L37: =IF(ISBLANK('Raw Data'!W$8),"",'Raw Data'!W$8)
C38: 22 | D38: =IF(ISBLANK('Raw Data'!X$9),"",'Raw Data'!X$9) | E38: =IF(ISBLANK('Raw Data'!X$1),"",'Raw Data'!X$1) | F38: =IF(ISBLANK('Raw Data'!X$2),"",'Raw Data'!X$2) | G38: =IF(ISBLANK('Raw Data'!X$3),"",'Raw Data'!X$3) | H38: =IF(ISBLANK('Raw Data'!X$4),"",'Raw Data'!X$4) | I38: =IF(ISBLANK('Raw Data'!X$5),"",'Raw Data'!X$5) | J38: =IF(ISBLANK('Raw Data'!X$6),"",'Raw Data'!X$6) | K38: =IF(ISBLANK('Raw Data'!X$7),"",'Raw Data'!X$7) | L38: =IF(ISBLANK('Raw Data'!X$8),"",'Raw Data'!X$8)
C39: 23 | D39: =IF(ISBLANK('Raw Data'!Y$9),"",'Raw Data'!Y$9) | E39: =IF(ISBLANK('Raw Data'!Y$1),"",'Raw Data'!Y$1) | F39: =IF(ISBLANK('Raw Data'!Y$2),"",'Raw Data'!Y$2) | G39: =IF(ISBLANK('Raw Data'!Y$3),"",'Raw Data'!Y$3) | H39: =IF(ISBLANK('Raw Data'!Y$4),"",'Raw Data'!Y$4) | I39: =IF(ISBLANK('Raw Data'!Y$5),"",'Raw Data'!Y$5) | J39: =IF(ISBLANK('Raw Data'!Y$6),"",'Raw Data'!Y$6) | K39: =IF(ISBLANK('Raw Data'!Y$7),"",'Raw Data'!Y$7) | L39: =IF(ISBLANK('Raw Data'!Y$8),"",'Raw Data'!Y$8)
C40: 24 | D40: =IF(ISBLANK('Raw Data'!Z$9),"",'Raw Data'!Z$9) | E40: =IF(ISBLANK('Raw Data'!Z$1),"",'Raw Data'!Z$1) | F40: =IF(ISBLANK('Raw Data'!Z$2),"",'Raw Data'!Z$2) | G40: =IF(ISBLANK('Raw Data'!Z$3),"",'Raw Data'!Z$3) | H40: =IF(ISBLANK('Raw Data'!Z$4),"",'Raw Data'!Z$4) | I40: =IF(ISBLANK('Raw Data'!Z$5),"",'Raw Data'!Z$5) | J40: =IF(ISBLANK('Raw Data'!Z$6),"",'Raw Data'!Z$6) | K40: =IF(ISBLANK('Raw Data'!Z$7),"",'Raw Data'!Z$7) | L40: =IF(ISBLANK('Raw Data'!Z$8),"",'Raw Data'!Z$8)
C41: 25 | D41: =IF(ISBLANK('Raw Data'!AA$9),"",'Raw Data'!AA$9) | E41: =IF(ISBLANK('Raw Data'!AA$1),"",'Raw Data'!AA$1) | F41: =IF(ISBLANK('Raw Data'!AA$2),"",'Raw Data'!AA$2) | G41: =IF(ISBLANK('Raw Data'!AA$3),"",'Raw Data'!AA$3) | H41: =IF(ISBLANK('Raw Data'!AA$4),"",'Raw Data'!AA$4) | I41: =IF(ISBLANK('Raw Data'!AA$5),"",'Raw Data'!AA$5) | J41: =IF(ISBLANK('Raw Data'!AA$6),"",'Raw Data'!AA$6) | K41: =IF(ISBLANK('Raw Data'!AA$7),"",'Raw Data'!AA$7) | L41: =IF(ISBLANK('Raw Data'!AA$8),"",'Raw Data'!AA$8)
C42: 26 | D42: =IF(ISBLANK('Raw Data'!AB$9),"",'Raw Data'!AB$9) | E42: =IF(ISBLANK('Raw Data'!AB$1),"",'Raw Data'!AB$1) | F42: =IF(ISBLANK('Raw Data'!AB$2),"",'Raw Data'!AB$2) | G42: =IF(ISBLANK('Raw Data'!AB$3),"",'Raw Data'!AB$3) | H42: =IF(ISBLANK('Raw Data'!AB$4),"",'Raw Data'!AB$4) | I42: =IF(ISBLANK('Raw Data'!AB$5),"",'Raw Data'!AB$5) | J42: =IF(ISBLANK('Raw Data'!AB$6),"",'Raw Data'!AB$6) | K42: =IF(ISBLANK('Raw Data'!AB$7),"",'Raw Data'!AB$7) | L42: =IF(ISBLANK('Raw Data'!AB$8),"",'Raw Data'!AB$8)
C43: 27 | D43: =IF(ISBLANK('Raw Data'!AC$9),"",'Raw Data'!AC$9) | E43: =IF(ISBLANK('Raw Data'!AC$1),"",'Raw Data'!AC$1) | F43: =IF(ISBLANK('Raw Data'!AC$2),"",'Raw Data'!AC$2) | G43: =IF(ISBLANK('Raw Data'!AC$3),"",'Raw Data'!AC$3) | H43: =IF(ISBLANK('Raw Data'!AC$4),"",'Raw Data'!AC$4) | I43: =IF(ISBLANK('Raw Data'!AC$5),"",'Raw Data'!AC$5) | J43: =IF(ISBLANK('Raw Data'!AC$6),"",'Raw Data'!AC$6) | K43: =IF(ISBLANK('Raw Data'!AC$7),"",'Raw Data'!AC$7) | L43: =IF(ISBLANK('Raw Data'!AC$8),"",'Raw Data'!AC$8)
C44: 28 | D44: =IF(ISBLANK('Raw Data'!AD$9),"",'Raw Data'!AD$9) | E44: =IF(ISBLANK('Raw Data'!AD$1),"",'Raw Data'!AD$1) | F44: =IF(ISBLANK('Raw Data'!AD$2),"",'Raw Data'!AD$2) | G44: =IF(ISBLANK('Raw Data'!AD$3),"",'Raw Data'!AD$3) | H44: =IF(ISBLANK('Raw Data'!AD$4),"",'Raw Data'!AD$4) | I44: =IF(ISBLANK('Raw Data'!AD$5),"",'Raw Data'!AD$5) | J44: =IF(ISBLANK('Raw Data'!AD$6),"",'Raw Data'!AD$6) | K44: =IF(ISBLANK('Raw Data'!AD$7),"",'Raw Data'!AD$7) | L44: =IF(ISBLANK('Raw Data'!AD$8),"",'Raw Data'!AD$8)
C45: 29 | D45: =IF(ISBLANK('Raw Data'!AE$9),"",'Raw Data'!AE$9) | E45: =IF(ISBLANK('Raw Data'!AE$1),"",'Raw Data'!AE$1) | F45: =IF(ISBLANK('Raw Data'!AE$2),"",'Raw Data'!AE$2) | G45: =IF(ISBLANK('Raw Data'!AE$3),"",'Raw Data'!AE$3) | H45: =IF(ISBLANK('Raw Data'!AE$4),"",'Raw Data'!AE$4) | I45: =IF(ISBLANK('Raw Data'!AE$5),"",'Raw Data'!AE$5) | J45: =IF(ISBLANK('Raw Data'!AE$6),"",'Raw Data'!AE$6) | K45: =IF(ISBLANK('Raw Data'!AE$7),"",'Raw Data'!AE$7) | L45: =IF(ISBLANK('Raw Data'!AE$8),"",'Raw Data'!AE$8)
C46: 30 | D46: =IF(ISBLANK('Raw Data'!AF$9),"",'Raw Data'!AF$9) | E46: =IF(ISBLANK('Raw Data'!AF$1),"",'Raw Data'!AF$1) | F46: =IF(ISBLANK('Raw Data'!AF$2),"",'Raw Data'!AF$2) | G46: =IF(ISBLANK('Raw Data'!AF$3),"",'Raw Data'!AF$3) | H46: =IF(ISBLANK('Raw Data'!AF$4),"",'Raw Data'!AF$4) | I46: =IF(ISBLANK('Raw Data'!AF$5),"",'Raw Data'!AF$5) | J46: =IF(ISBLANK('Raw Data'!AF$6),"",'Raw Data'!AF$6) | K46: =IF(ISBLANK('Raw Data'!AF$7),"",'Raw Data'!AF$7) | L46: =IF(ISBLANK('Raw Data'!AF$8),"",'Raw Data'!AF$8)
C47: 31 | D47: =IF(ISBLANK('Raw Data'!AG$9),"",'Raw Data'!AG$9) | E47: =IF(ISBLANK('Raw Data'!AG$1),"",'Raw Data'!AG$1) | F47: =IF(ISBLANK('Raw Data'!AG$2),"",'Raw Data'!AG$2) | G47: =IF(ISBLANK('Raw Data'!AG$3),"",'Raw Data'!AG$3) | H47: =IF(ISBLANK('Raw Data'!AG$4),"",'Raw Data'!AG$4) | I47: =IF(ISBLANK('Raw Data'!AG$5),"",'Raw Data'!AG$5) | J47: =IF(ISBLANK('Raw Data'!AG$6),"",'Raw Data'!AG$6) | K47: =IF(ISBLANK('Raw Data'!AG$7),"",'Raw Data'!AG$7) | L47: =IF(ISBLANK('Raw Data'!AG$8),"",'Raw Data'!AG$8)
C48: 32 | D48: =IF(ISBLANK('Raw Data'!AH$9),"",'Raw Data'!AH$9) | E48: =IF(ISBLANK('Raw Data'!AH$1),"",'Raw Data'!AH$1) | F48: =IF(ISBLANK('Raw Data'!AH$2),"",'Raw Data'!AH$2) | G48: =IF(ISBLANK('Raw Data'!AH$3),"",'Raw Data'!AH$3) | H48: =IF(ISBLANK('Raw Data'!AH$4),"",'Raw Data'!AH$4) | I48: =IF(ISBLANK('Raw Data'!AH$5),"",'Raw Data'!AH$5) | J48: =IF(ISBLANK('Raw Data'!AH$6),"",'Raw Data'!AH$6) | K48: =IF(ISBLANK('Raw Data'!AH$7),"",'Raw Data'!AH$7) | L48: =IF(ISBLANK('Raw Data'!AH$8),"",'Raw Data'!AH$8)
C49: 33 | D49: =IF(ISBLANK('Raw Data'!AI$9),"",'Raw Data'!AI$9) | E49: =IF(ISBLANK('Raw Data'!AI$1),"",'Raw Data'!AI$1) | F49: =IF(ISBLANK('Raw Data'!AI$2),"",'Raw Data'!AI$2) | G49: =IF(ISBLANK('Raw Data'!AI$3),"",'Raw Data'!AI$3) | H49: =IF(ISBLANK('Raw Data'!AI$4),"",'Raw Data'!AI$4) | I49: =IF(ISBLANK('Raw Data'!AI$5),"",'Raw Data'!AI$5) | J49: =IF(ISBLANK('Raw Data'!AI$6),"",'Raw Data'!AI$6) | K49: =IF(ISBLANK('Raw Data'!AI$7),"",'Raw Data'!AI$7) | L49: =IF(ISBLANK('Raw Data'!AI$8),"",'Raw Data'!AI$8)
C50: 34 | D50: =IF(ISBLANK('Raw Data'!AJ$9),"",'Raw Data'!AJ$9) | E50: =IF(ISBLANK('Raw Data'!AJ$1),"",'Raw Data'!AJ$1) | F50: =IF(ISBLANK('Raw Data'!AJ$2),"",'Raw Data'!AJ$2) | G50: =IF(ISBLANK('Raw Data'!AJ$3),"",'Raw Data'!AJ$3) | H50: =IF(ISBLANK('Raw Data'!AJ$4),"",'Raw Data'!AJ$4) | I50: =IF(ISBLANK('Raw Data'!AJ$5),"",'Raw Data'!AJ$5) | J50: =IF(ISBLANK('Raw Data'!AJ$6),"",'Raw Data'!AJ$6) | K50: =IF(ISBLANK('Raw Data'!AJ$7),"",'Raw Data'!AJ$7) | L50: =IF(ISBLANK('Raw Data'!AJ$8),"",'Raw Data'!AJ$8)
C51: 35 | D51: =IF(ISBLANK('Raw Data'!AK$9),"",'Raw Data'!AK$9) | E51: =IF(ISBLANK('Raw Data'!AK$1),"",'Raw Data'!AK$1) | F51: =IF(ISBLANK('Raw Data'!AK$2),"",'Raw Data'!AK$2) | G51: =IF(ISBLANK('Raw Data'!AK$3),"",'Raw Data'!AK$3) | H51: =IF(ISBLANK('Raw Data'!AK$4),"",'Raw Data'!AK$4) | I51: =IF(ISBLANK('Raw Data'!AK$5),"",'Raw Data'!AK$5) | J51: =IF(ISBLANK('Raw Data'!AK$6),"",'Raw Data'!AK$6) | K51: =IF(ISBLANK('Raw Data'!AK$7),"",'Raw Data'!AK$7) | L51: =IF(ISBLANK('Raw Data'!AK$8),"",'Raw Data'!AK$8)
C52: 36 | D52: =IF(ISBLANK('Raw Data'!AL$9),"",'Raw Data'!AL$9) | E52: =IF(ISBLANK('Raw Data'!AL$1),"",'Raw Data'!AL$1) | F52: =IF(ISBLANK('Raw Data'!AL$2),"",'Raw Data'!AL$2) | G52: =IF(ISBLANK('Raw Data'!AL$3),"",'Raw Data'!AL$3) | H52: =IF(ISBLANK('Raw Data'!AL$4),"",'Raw Data'!AL$4) | I52: =IF(ISBLANK('Raw Data'!AL$5),"",'Raw Data'!AL$5) | J52: =IF(ISBLANK('Raw Data'!AL$6),"",'Raw Data'!AL$6) | K52: =IF(ISBLANK('Raw Data'!AL$7),"",'Raw Data'!AL$7) | L52: =IF(ISBLANK('Raw Data'!AL$8),"",'Raw Data'!AL$8)
C53: 37 | D53: =IF(ISBLANK('Raw Data'!AM$9),"",'Raw Data'!AM$9) | E53: =IF(ISBLANK('Raw Data'!AM$1),"",'Raw Data'!AM$1) | F53: =IF(ISBLANK('Raw Data'!AM$2),"",'Raw Data'!AM$2) | G53: =IF(ISBLANK('Raw Data'!AM$3),"",'Raw Data'!AM$3) | H53: =IF(ISBLANK('Raw Data'!AM$4),"",'Raw Data'!AM$4) | I53: =IF(ISBLANK('Raw Data'!AM$5),"",'Raw Data'!AM$5) | J53: =IF(ISBLANK('Raw Data'!AM$6),"",'Raw Data'!AM$6) | K53: =IF(ISBLANK('Raw Data'!AM$7),"",'Raw Data'!AM$7) | L53: =IF(ISBLANK('Raw Data'!AM$8),"",'Raw Data'!AM$8)
C54: 38 | D54: =IF(ISBLANK('Raw Data'!AN$9),"",'Raw Data'!AN$9) | E54: =IF(ISBLANK('Raw Data'!AN$1),"",'Raw Data'!AN$1) | F54: =IF(ISBLANK('Raw Data'!AN$2),"",'Raw Data'!AN$2) | G54: =IF(ISBLANK('Raw Data'!AN$3),"",'Raw Data'!AN$3) | H54: =IF(ISBLANK('Raw Data'!AN$4),"",'Raw Data'!AN$4) | I54: =IF(ISBLANK('Raw Data'!AN$5),"",'Raw Data'!AN$5) | J54: =IF(ISBLANK('Raw Data'!AN$6),"",'Raw Data'!AN$6) | K54: =IF(ISBLANK('Raw Data'!AN$7),"",'Raw Data'!AN$7) | L54: =IF(ISBLANK('Raw Data'!AN$8),"",'Raw Data'!AN$8)
C55: 39 | D55: =IF(ISBLANK('Raw Data'!AO$9),"",'Raw Data'!AO$9) | E55: =IF(ISBLANK('Raw Data'!AO$1),"",'Raw Data'!AO$1) | F55: =IF(ISBLANK('Raw Data'!AO$2),"",'Raw Data'!AO$2) | G55: =IF(ISBLANK('Raw Data'!AO$3),"",'Raw Data'!AO$3) | H55: =IF(ISBLANK('Raw Data'!AO$4),"",'Raw Data'!AO$4) | I55: =IF(ISBLANK('Raw Data'!AO$5),"",'Raw Data'!AO$5) | J55: =IF(ISBLANK('Raw Data'!AO$6),"",'Raw Data'!AO$6) | K55: =IF(ISBLANK('Raw Data'!AO$7),"",'Raw Data'!AO$7) | L55: =IF(ISBLANK('Raw Data'!AO$8),"",'Raw Data'!AO$8)
...

Sheet Raw Data
B1: Time | C1: 15:51 | D1: 15:53 | E1: 15:54 | F1: 15:56 | G1: 15:57 | H1: 15:59 | I1: 16:00 | J1: 16:02 | K1: 16:03 | L1: 16:05 | M1: 16:06 | N1: 16:08 | O1: 16:09 | P1: 16:11 | Q1: 16:12 | R1: 16:14 | S1: 16:15
B2: Date | C2: 2026-04-14 | D2: 2026-04-14 | E2: 2026-04-14 | F2: 2026-04-14 | G2: 2026-04-14 | H2: 2026-04-14 | I2: 2026-04-14 | J2: 2026-04-14 | K2: 2026-04-14 | L2: 2026-04-14 | M2: 2026-04-14 | N2: 2026-04-14 | O2: 2026-04-14 | P2: 2026-04-14 | Q2: 2026-04-14 | R2: 2026-04-14 | S2: 2026-04-14
B3: Cassette Identifier Code | C3: 08DE9A3D94480732 | D3: 08DE9A3DD2703B09 | E3: 08DE9A3E031FB3EA | F3: 08DE9A3E32D405C1 | G3: 08DE9A3E624976D2 | H3: 08DE9A3E9EB97FE6 | I3: 08DE9A3ED28AE09F | J3: 08DE9A3F0A44C2AB | K3: 08DE9A3F3DC20285 | L3: 08DE9A3F7A855DCE | M3: 08DE9A3FA7D92665 | N3: 08DE9A3FDD2F8DE0 | O3: 08DE9A401AE615B9 | P3: 08DE9A404B9EF17E | Q3: 08DE9A407DEE6BE3 | R3: 08DE9A40B5D0ADF5 | S3: 08DE9A40E5ED76F5
B4: Sample ID | C4: 1 | D4: 1 | E4: 1 | F4: 1 | G4: 1 | H4: 1 | I4: 1 | J4: 1 | K4: 1 | L4: 1 | M4: 1 | N4: 1 | O4: 1 | P4: 1 | Q4: 1 | R4: 1 | S4: 1
B5: Result | C5: Positive | D5: Positive | E5: Negative | F5: Negative | G5: Negative | H5: Negative | I5: Negative | J5: Positive | K5: Positive | L5: Negative | M5: Positive | N5: Negative | O5: Negative | P5: Negative | Q5: Negative | R5: Positive | S5: Positive
B6: Method | C6: NanoFast Listeria spp | D6: NanoFast Listeria spp | E6: NanoFast Listeria spp | F6: NanoFast Listeria spp | G6: NanoFast Listeria spp | H6: NanoFast Listeria spp | I6: NanoFast Listeria spp | J6: NanoFast Listeria spp | K6: NanoFast Listeria spp | L6: NanoFast Listeria spp | M6: NanoFast Listeria spp | N6: NanoFast Listeria spp | O6: NanoFast Listeria spp | P6: NanoFast Listeria spp | Q6: NanoFast Listeria spp | R6: NanoFast Listeria spp | S6: NanoFast Listeria spp
B7: Version | C7: 9 | D7: 9 | E7: 9 | F7: 9 | G7: 9 | H7: 9 | I7: 9 | J7: 9 | K7: 9 | L7: 9 | M7: 9 | N7: 9 | O7: 9 | P7: 9 | Q7: 9 | R7: 9 | S7: 9
B8: Lot Code | C8: 62 | D8: 62 | E8: 62 | F8: 62 | G8: 62 | H8: 62 | I8: 62 | J8: 62 | K8: 62 | L8: 62 | M8: 62 | N8: 62 | O8: 62 | P8: 62 | Q8: 62 | R8: 62 | S8: 62
B9: Instrument Number | C9: RONIA-PILOT-32 | D9: RONIA-PILOT-32 | E9: RONIA-PILOT-32 | F9: RONIA-PILOT-32 | G9: RONIA-PILOT-32 | H9: RONIA-PILOT-32 | I9: RONIA-PILOT-32 | J9: RONIA-PILOT-32 | K9: RONIA-PILOT-32 | L9: RONIA-PILOT-32 | M9: RONIA-PILOT-32 | N9: RONIA-PILOT-32 | O9: RONIA-PILOT-32 | P9: RONIA-PILOT-32 | Q9: RONIA-PILOT-32 | R9: RONIA-PILOT-32 | S9: RONIA-PILOT-32
B10: 1 | C10: 25164477 | D10: 25164117 | E10: 25152529 | F10: 25149121 | G10: 25183789 | H10: 25186293 | I10: 25169953 | J10: 25162065 | K10: 25167349 | L10: 25221153 | M10: 25187105 | N10: 25184121 | O10: 25206217 | P10: 25223233 | Q10: 25198073 | R10: 25206553 | S10: 25209437
B11: 2 | C11: 25157341 | D11: 25166129 | E11: 25148029 | F11: 25180525 | G11: 25186805 | H11: 25188221 | I11: 25172273 | J11: 25162925 | K11: 25174905 | L11: 25224277 | M11: 25179625 | N11: 25191617 | O11: 25196825 | P11: 25214057 | Q11: 25180721 | R11: 25193681 | S11: 25214937
B12: 3 | C12: 25262109 | D12: 25269169 | E12: 25264473 | F12: 25268509 | G12: 25297893 | H12: 25294861 | I12: 25278281 | J12: 25297225 | K12: 25298517 | L12: 25326673 | M12: 25316233 | N12: 25309309 | O12: 25289245 | P12: 25326153 | Q12: 25294649 | R12: 25290561 | S12: 25314705
B13: 4 | C13: 25321325 | D13: 25314169 | E13: 25321645 | F13: 25322881 | G13: 25366197 | H13: 25359557 | I13: 25361125 | J13: 25354957 | K13: 25367109 | L13: 25374909 | M13: 25368505 | N13: 25367301 | O13: 25395525 | P13: 25388525 | Q13: 25380809 | R13: 25376637 | S13: 25362601
B14: 5 | C14: 25361553 | D14: 25331961 | E14: 25386873 | F14: 25355089 | G14: 25377869 | H14: 25364005 | I14: 25394617 | J14: 25395945 | K14: 25401189 | L14: 25369669 | M14: 25409313 | N14: 25421329 | O14: 25433129 | P14: 25415577 | Q14: 25396017 | R14: 25388325 | S14: 25402333
B15: 6 | C15: 25384165 | D15: 25381957 | E15: 25422813 | F15: 25379969 | G15: 25403429 | H15: 25372245 | I15: 25415853 | J15: 25443525 | K15: 25405393 | L15: 25396857 | M15: 25433917 | N15: 25453669 | O15: 25417721 | P15: 25421169 | Q15: 25401837 | R15: 25405381 | S15: 25419661
B16: 7 | C16: 25402525 | D16: 25410641 | E16: 25379065 | F16: 25366073 | G16: 25403265 | H16: 25393605 | I16: 25430985 | J16: 25470157 | K16: 25414001 | L16: 25412793 | M16: 25437497 | N16: 25468645 | O16: 25400553 | P16: 25453513 | Q16: 25417389 | R16: 25415001 | S16: 25392489
B17: 8 | C17: 25402201 | D17: 25406121 | E17: 25358821 | F17: 25370937 | G17: 25409381 | H17: 25428913 | I17: 25433609 | J17: 25451121 | K17: 25399085 | L17: 25427725 | M17: 25422841 | N17: 25446605 | O17: 25421781 | P17: 25449357 | Q17: 25410409 | R17: 25430353 | S17: 25436717
B18: 9 | C18: 25411561 | D18: 25401977 | E18: 25362793 | F18: 25387865 | G18: 25441641 | H18: 25448865 | I18: 25419665 | J18: 25412489 | K18: 25439845 | L18: 25414665 | M18: 25418265 | N18: 25468333 | O18: 25407253 | P18: 25454937 | Q18: 25418465 | R18: 25452137 | S18: 25427453
B19: 10 | C19: 25431253 | D19: 25410641 | E19: 25364485 | F19: 25381661 | G19: 25444809 | H19: 25429849 | I19: 25413525 | J19: 25443673 | K19: 25456973 | L19: 25438005 | M19: 25437293 | N19: 25465417 | O19: 25443597 | P19: 25485557 | Q19: 25455589 | R19: 25471013 | S19: 25446373
B20: 11 | C20: 25404045 | D20: 25395621 | E20: 25376505 | F20: 25400445 | G20: 25441849 | H20: 25443365 | I20: 25415377 | J20: 25457581 | K20: 25425617 | L20: 25419977 | M20: 25441441 | N20: 25437713 | O20: 25425953 | P20: 25479097 | Q20: 25450053 | R20: 25454313 | S20: 25440653
B21: 12 | C21: 25394113 | D21: 25384089 | E21: 25384405 | F21: 25380877 | G21: 25432181 | H21: 25437165 | I21: 25406829 | J21: 25464953 | K21: 25402501 | L21: 25397473 | M21: 25428545 | N21: 25445041 | O21: 25447161 | P21: 25445145 | Q21: 25418713 | R21: 25460557 | S21: 25441617
... B288: 279 | C288: 30550117 | D288: 27486133 | E288: 28135857 | F288: 32080657 | G288: 30223961 | H288: 27055641 | I288: 34173633 | J288: 33229193 | K288: 36038065 | L288: 29344893 | M288: 34429661 | N288: 32077089 | O288: 30856705 | P288: 34153129 | Q288: 29452477 | R288: 28337493 | S288: 33717653
B289: 280

Sheet Presented Data
B1: Time
B2: Date
B3: Cassette Identifier Code
B4: Sample ID | C4: =IF(Results!$M17="Yes",'Raw Data'!C4,"") | D4: =IF(Results!$M18="Yes",'Raw Data'!D4,"") | E4: =IF(Results!$M19="Yes",'Raw Data'!E4,"") | F4: =IF(Results!$M20="Yes",'Raw Data'!F4,"") | G4: =IF(Results!$M21="Yes",'Raw Data'!G4,"") | H4: =IF(Results!$M22="Yes",'Raw Data'!H4,"") | I4: =IF(Results!$M23="Yes",'Raw Data'!I4,"") | J4: =IF(Results!$M24="Yes",'Raw Data'!J4,"") | K4: =IF(Results!$M25="Yes",'Raw Data'!K4,"") | L4: =IF(Results!$M26="Yes",'Raw Data'!L4,"") | M4: =IF(Results!$M27="Yes",'Raw Data'!M4,"") | N4: =IF(Results!$M28="Yes",'Raw Data'!N4,"") | O4: =IF(Results!$M29="Yes",'Raw Data'!O4,"") | P4: =IF(Results!$M30="Yes",'Raw Data'!P4,"") | Q4: =IF(Results!$M31="Yes",'Raw Data'!Q4,"") | R4: =IF(Results!$M32="Yes",'Raw Data'!R4,"") | S4: =IF(Results!$M33="Yes",'Raw Data'!S4,"") | T4: =IF(Results!$M34="Yes",'Raw Data'!T4,"") | U4: =IF(Results!$M35="Yes",'Raw Data'!U4,"") | V4: =IF(Results!$M36="Yes",'Raw Data'!V4,"") | W4: =IF(Results!$M37="Yes",'Raw Data'!W4,"") | X4: =IF(Results!$M38="Yes",'Raw Data'!X4,"") | Y4: =IF(Results!$M39="Yes",'Raw Data'!Y4,"") | Z4: =IF(Results!$M40="Yes",'Raw Data'!Z4,"") | AA4: =IF(Results!$M41="Yes",'Raw Data'!AA4,"") | AB4: =IF(Results!$M42="Yes",'Raw Data'!AB4,"") | AC4: =IF(Results!$M43="Yes",'Raw Data'!AC4,"") | AD4: =IF(Results!$M44="Yes",'Raw Data'!AD4,"") | AE4: =IF(Results!$M45="Yes",'Raw Data'!AE4,"") | AF4: =IF(Results!$M46="Yes",'Raw Data'!AF4,"") | AG4: =IF(Results!$M47="Yes",'Raw Data'!AG4,"") | AH4: =IF(Results!$M48="Yes",'Raw Data'!AH4,"") | AI4: =IF(Results!$M49="Yes",'Raw Data'!AI4,"") | AJ4: =IF(Results!$M50="Yes",'Raw Data'!AJ4,"") | AK4: =IF(Results!$M51="Yes",'Raw Data'!AK4,"") | AL4: =IF(Results!$M52="Yes",'Raw Data'!AL4,"") | AM4: =IF(Results!$M53="Yes",'Raw Data'!AM4,"") | AN4: =IF(Results!$M54="Yes",'Raw Data'!AN4,"") | AO4: =IF(Results!$M55="Yes",'Raw Data'!AO4,"") | AP4: =IF(Results!$M56="Yes",'Raw Data'!AP4,"")
B5: Result
B6: Method
B7: Version
A8: Graph title | B8: Lot Code | D8: =SUBSTITUTE(_xlfn.TEXTJOIN(", ",TRUE,'Presented Data'!C4:AP4),","," and",MAX(1,COUNTA('Presented Data'!C4:AP4)-1))
A9: =SUBSTITUTE(_xlfn.TEXTJOIN(", ",TRUE,'Presented Data'!C4:AP4),","," and",MAX(1,COUNTA('Presented Data'!C4:AP4)-1)) | B9: Instrument Number
B10: 1 | C10: =IF(Results!$M$17="Yes",'Raw Data'!C10-'Raw Data'!C$10,"") | D10: =IF(Results!$M$18="Yes",'Raw Data'!D10-'Raw Data'!D$10,"") | E10: =IF(Results!$M$19="Yes",'Raw Data'!E10-'Raw Data'!E$10,"") | F10: =IF(Results!$M$20="Yes",'Raw Data'!F10-'Raw Data'!F$10,"") | G10: =IF(Results!$M$21="Yes",'Raw Data'!G10-'Raw Data'!G$10,"") | H10: =IF(Results!$M$22="Yes",'Raw Data'!H10-'Raw Data'!H$10,"") | I10: =IF(Results!$M$23="Yes",'Raw Data'!I10-'Raw Data'!I$10,"") | J10: =IF(Results!$M$24="Yes",'Raw Data'!J10-'Raw Data'!J$10,"") | K10: =IF(Results!$M$25="Yes",'Raw Data'!K10-'Raw Data'!K$10,"") | L10: =IF(Results!$M$26="Yes",'Raw Data'!L10-'Raw Data'!L$10,"") | M10: =IF(Results!$M$27="Yes",'Raw Data'!M10-'Raw Data'!M$10,"") | N10: =IF(Results!$M$28="Yes",'Raw Data'!N10-'Raw Data'!N$10,"") | O10: =IF(Results!$M$29="Yes",'Raw Data'!O10-'Raw Data'!O$10,"") | P10: =IF(Results!$M$30="Yes",'Raw Data'!P10-'Raw Data'!P$10,"") | Q10: =IF(Results!$M$31="Yes",'Raw Data'!Q10-'Raw Data'!Q$10,"") | R10: =IF(Results!$M$32="Yes",'Raw Data'!R10-'Raw Data'!R$10,"") | S10: =IF(Results!$M$33="Yes",'Raw Data'!S10-'Raw Data'!S$10,"") | T10: =IF(Results!$M$34="Yes",'Raw Data'!T10-'Raw Data'!T$10,"") | U10: =IF(Results!$M$35="Yes",'Raw Data'!U10-'Raw Data'!U$10,"") | V10: =IF(Results!$M$36="Yes",'Raw Data'!V10-'Raw Data'!V$10,"") | W10: =IF(Results!$M$37="Yes",'Raw Data'!W10-'Raw Data'!W$10,"") | X10: =IF(Results!$M$38="Yes",'Raw Data'!X10-'Raw Data'!X$10,"") | Y10: =IF(Results!$M$39="Yes",'Raw Data'!Y10-'Raw Data'!Y$10,"") | Z10: =IF(Results!$M$40="Yes",'Raw Data'!Z10-'Raw Data'!Z$10,"") | AA10: =IF(Results!$M$41="Yes",'Raw Data'!AA10-'Raw Data'!AA$10,"") | AB10: =IF(Results!$M$42="Yes",'Raw Data'!AB10-'Raw Data'!AB$10,"") | AC10: =IF(Results!$M$43="Yes",'Raw Data'!AC10-'Raw Data'!AC$10,"") | AD10: =IF(Results!$M$44="Yes",'Raw Data'!AD10-'Raw Data'!AD$10,"") | AE10: =IF(Results!$M$45="Yes",'Raw Data'!AE10-'Raw Data'!AE$10,"") | AF10: =IF(Results!$M$46="Yes",'Raw Data'!AF10-'Raw Data'!AF$10,"") | AG10: =IF(Results!$M$47="Yes",'Raw Data'!AG10-'Raw Data'!AG$10,"") | AH10: =IF(Results!$M$48="Yes",'Raw Data'!AH10-'Raw Data'!AH$10,"") | AI10: =IF(Results!$M$49="Yes",'Raw Data'!AI10-'Raw Data'!AI$10,"") | AJ10: =IF(Results!$M$50="Yes",'Raw Data'!AJ10-'Raw Data'!AJ$10,"") | AK10: =IF(Results!$M$51="Yes",'Raw Data'!AK10-'Raw Data'!AK$10,"") | AL10: =IF(Results!$M$52="Yes",'Raw Data'!AL10-'Raw Data'!AL$10,"") | AM10: =IF(Results!$M$53="Yes",'Raw Data'!AM10-'Raw Data'!AM$10,"") | AN10: =IF(Results!$M$54="Yes",'Raw Data'!AN10-'Raw Data'!AN$10,"") | AO10: =IF(Results!$M$55="Yes",'Raw Data'!AO10-'Raw Data'!AO$10,"") | AP10: =IF(Results!$M$56="Yes",'Raw Data'!AP10-'Raw Data'!AP$10,"")
B11: 2 | C11: =IF(Results!$M$17="Yes",'Raw Data'!C11-'Raw Data'!C$10,"") | D11: =IF(Results!$M$18="Yes",'Raw Data'!D11-'Raw Data'!D$10,"") | E11: =IF(Results!$M$19="Yes",'Raw Data'!E11-'Raw Data'!E$10,"") | F11: =IF(Results!$M$20="Yes",'Raw Data'!F11-'Raw Data'!F$10,"") | G11: =IF(Results!$M$21="Yes",'Raw Data'!G11-'Raw Data'!G$10,"") | H11: =IF(Results!$M$22="Yes",'Raw Data'!H11-'Raw Data'!H$10,"") | I11: =IF(Results!$M$23="Yes",'Raw Data'!I11-'Raw Data'!I$10,"") | J11: =IF(Results!$M$24="Yes",'Raw Data'!J11-'Raw Data'!J$10,"") | K11: =IF(Results!$M$25="Yes",'Raw Data'!K11-'Raw Data'!K$10,"") | L11: =IF(Results!$M$26="Yes",'Raw Data'!L11-'Raw Data'!L$10,"") | M11: =IF(Results!$M$27="Yes",'Raw Data'!M11-'Raw Data'!M$10,"") | N11: =IF(Results!$M$28="Yes",'Raw Data'!N11-'Raw Data'!N$10,"") | O11: =IF(Results!$M$29="Yes",'Raw Data'!O11-'Raw Data'!O$10,"") | P11: =IF(Results!$M$30="Yes",'Raw Data'!P11-'Raw Data'!P$10,"") | Q11: =IF(Results!$M$31="Yes",'Raw Data'!Q11-'Raw Data'!Q$10,"") | R11: =IF(Results!$M$32="Yes",'Raw Data'!R11-'Raw Data'!R$10,"") | S11: =IF(Results!$M$33="Yes",'Raw Data'!S11-'Raw Data'!S$10,"") | T11: =IF(Results!$M$34="Yes",'Raw Data'!T11-'Raw Data'!T$10,"") | U11: =IF(Results!$M$35="Yes",'Raw Data'!U11-'Raw Data'!U$10,"") | V11: =IF(Results!$M$36="Yes",'Raw Data'!V11-'Raw Data'!V$10,"") | W11: =IF(Results!$M$37="Yes",'Raw Data'!W11-'Raw Data'!W$10,"") | X11: =IF(Results!$M$38="Yes",'Raw Data'!X11-'Raw Data'!X$10,"") | Y11: =IF(Results!$M$39="Yes",'Raw Data'!Y11-'Raw Data'!Y$10,"") | Z11: =IF(Results!$M$40="Yes",'Raw Data'!Z11-'Raw Data'!Z$10,"") | AA11: =IF(Results!$M$41="Yes",'Raw Data'!AA11-'Raw Data'!AA$10,"") | AB11: =IF(Results!$M$42="Yes",'Raw Data'!AB11-'Raw Data'!AB$10,"") | AC11: =IF(Results!$M$43="Yes",'Raw Data'!AC11-'Raw Data'!AC$10,"") | AD11: =IF(Results!$M$44="Yes",'Raw Data'!AD11-'Raw Data'!AD$10,"") | AE11: =IF(Results!$M$45="Yes",'Raw Data'!AE11-'Raw Data'!AE$10,"") | AF11: =IF(Results!$M$46="Yes",'Raw Data'!AF11-'Raw Data'!AF$10,"") | AG11: =IF(Results!$M$47="Yes",'Raw Data'!AG11-'Raw Data'!AG$10,"") | AH11: =IF(Results!$M$48="Yes",'Raw Data'!AH11-'Raw Data'!AH$10,"") | AI11: =IF(Results!$M$49="Yes",'Raw Data'!AI11-'Raw Data'!AI$10,"") | AJ11: =IF(Results!$M$50="Yes",'Raw Data'!AJ11-'Raw Data'!AJ$10,"") | AK11: =IF(Results!$M$51="Yes",'Raw Data'!AK11-'Raw Data'!AK$10,"") | AL11: =IF(Results!$M$52="Yes",'Raw Data'!AL11-'Raw Data'!AL$10,"") | AM11: =IF(Results!$M$53="Yes",'Raw Data'!AM11-'Raw Data'!AM$10,"") | AN11: =IF(Results!$M$54="Yes",'Raw Data'!AN11-'Raw Data'!AN$10,"") | AO11: =IF(Results!$M$55="Yes",'Raw Data'!AO11-'Raw Data'!AO$10,"") | AP11: =IF(Results!$M$56="Yes",'Raw Data'!AP11-'Raw Data'!AP$10,"")
B12: 3 | C12: =IF(Results!$M$17="Yes",'Raw Data'!C12-'Raw Data'!C$10,"") | D12: =IF(Results!$M$18="Yes",'Raw Data'!D12-'Raw Data'!D$10,"") | E12: =IF(Results!$M$19="Yes",'Raw Data'!E12-'Raw Data'!E$10,"") | F12: =IF(Results!$M$20="Yes",'Raw Data'!F12-'Raw Data'!F$10,"") | G12: =IF(Results!$M$21="Yes",'Raw Data'!G12-'Raw Data'!G$10,"") | H12: =IF(Results!$M$22="Yes",'Raw Data'!H12-'Raw Data'!H$10,"") | I12: =IF(Results!$M$23="Yes",'Raw Data'!I12-'Raw Data'!I$10,"") | J12: =IF(Results!$M$24="Yes",'Raw Data'!J12-'Raw Data'!J$10,"") | K12: =IF(Results!$M$25="Yes",'Raw Data'!K12-'Raw Data'!K$10,"") | L12: =IF(Results!$M$26="Yes",'Raw Data'!L12-'Raw Data'!L$10,"") | M12: =IF(Results!$M$27="Yes",'Raw Data'!M12-'Raw Data'!M$10,"") | N12: =IF(Results!$M$28="Yes",'Raw Data'!N12-'Raw Data'!N$10,"") | O12: =IF(Results!$M$29="Yes",'Raw Data'!O12-'Raw Data'!O$10,"") | P12: =IF(Results!$M$30="Yes",'Raw Data'!P12-'Raw Data'!P$10,"") | Q12: =IF(Results!$M$31="Yes",'Raw Data'!Q12-'Raw Data'!Q$10,"") | R12: =IF(Results!$M$32="Yes",'Raw Data'!R12-'Raw Data'!R$10,"") | S12: =IF(Results!$M$33="Yes",'Raw Data'!S12-'Raw Data'!S$10,"") | T12: =IF(Results!$M$34="Yes",'Raw Data'!T12-'Raw Data'!T$10,"") | U12: =IF(Results!$M$35="Yes",'Raw Data'!U12-'Raw Data'!U$10,"") | V12: =IF(Results!$M$36="Yes",'Raw Data'!V12-'Raw Data'!V$10,"") | W12: =IF(Results!$M$37="Yes",'Raw Data'!W12-'Raw Data'!W$10,"") | X12: =IF(Results!$M$38="Yes",'Raw Data'!X12-'Raw Data'!X$10,"") | Y12: =IF(Results!$M$39="Yes",'Raw Data'!Y12-'Raw Data'!Y$10,"") | Z12: =IF(Results!$M$40="Yes",'Raw Data'!Z12-'Raw Data'!Z$10,"") | AA12: =IF(Results!$M$41="Yes",'Raw Data'!AA12-'Raw Data'!AA$10,"") | AB12: =IF(Results!$M$42="Yes",'Raw Data'!AB12-'Raw Data'!AB$10,"") | AC12: =IF(Results!$M$43="Yes",'Raw Data'!AC12-'Raw Data'!AC$10,"") | AD12: =IF(Results!$M$44="Yes",'Raw Data'!AD12-'Raw Data'!AD$10,"") | AE12: =IF(Results!$M$45="Yes",'Raw Data'!AE12-'Raw Data'!AE$10,"") | AF12: =IF(Results!$M$46="Yes",'Raw Data'!AF12-'Raw Data'!AF$10,"") | AG12: =IF(Results!$M$47="Yes",'Raw Data'!AG12-'Raw Data'!AG$10,"") | AH12: =IF(Results!$M$48="Yes",'Raw Data'!AH12-'Raw Data'!AH$10,"") | AI12: =IF(Results!$M$49="Yes",'Raw Data'!AI12-'Raw Data'!AI$10,"") | AJ12: =IF(Results!$M$50="Yes",'Raw Data'!AJ12-'Raw Data'!AJ$10,"") | AK12: =IF(Results!$M$51="Yes",'Raw Data'!AK12-'Raw Data'!AK$10,"") | AL12: =IF(Results!$M$52="Yes",'Raw Data'!AL12-'Raw Data'!AL$10,"") | AM12: =IF(Results!$M$53="Yes",'Raw Data'!AM12-'Raw Data'!AM$10,"") | AN12: =IF(Results!$M$54="Yes",'Raw Data'!AN12-'Raw Data'!AN$10,"") | AO12: =IF(Results!$M$55="Yes",'Raw Data'!AO12-'Raw Data'!AO$10,"") | AP12: =IF(Results!$M$56="Yes",'Raw Data'!AP12-'Raw Data'!AP$10,"")
B13: 4 | C13: =IF(Results!$M$17="Yes",'Raw Data'!C13-'Raw Data'!C$10,"") | D13: =IF(Results!$M$18="Yes",'Raw Data'!D13-'Raw Data'!D$10,"") | E13: =IF(Results!$M$19="Yes",'Raw Data'!E13-'Raw Data'!E$10,"") | F13: =IF(Results!$M$20="Yes",'Raw Data'!F13-'Raw Data'!F$10,"") | G13: =IF(Results!$M$21="Yes",'Raw Data'!G13-'Raw Data'!G$10,"") | H13: =IF(Results!$M$22="Yes",'Raw Data'!H13-'Raw Data'!H$10,"") | I13: =IF(Results!$M$23="Yes",'Raw Data'!I13-'Raw Data'!I$10,"") | J13: =IF(Results!$M$24="Yes",'Raw Data'!J13-'Raw Data'!J$10,"") | K13: =IF(Results!$M$25="Yes",'Raw Data'!K13-'Raw Data'!K$10,"") | L13: =IF(Results!$M$26="Yes",'Raw Data'!L13-'Raw Data'!L$10,"") | M13: =IF(Results!$M$27="Yes",'Raw Data'!M13-'Raw Data'!M$10,"") | N13: =IF(Results!$M$28="Yes",'Raw Data'!N13-'Raw Data'!N$10,"") | O13: =IF(Results!$M$29="Yes",'Raw Data'!O13-'Raw Data'!O$10,"") | P13: =IF(Results!$M$30="Yes",'Raw Data'!P13-'Raw Data'!P$10,"") | Q13: =IF(Results!$M$31="Yes",'Raw Data'!Q13-'Raw Data'!Q$10,"") | R13: =IF(Results!$M$32="Yes",'Raw Data'!R13-'Raw Data'!R$10,"") | S13: =IF(Results!$M$33="Yes",'Raw Data'!S13-'Raw Data'!S$10,"") | T13: =IF(Results!$M$34="Yes",'Raw Data'!T13-'Raw Data'!T$10,"") | U13: =IF(Results!$M$35="Yes",'Raw Data'!U13-'Raw Data'!U$10,"") | V13: =IF(Results!$M$36="Yes",'Raw Data'!V13-'Raw Data'!V$10,"") | W13: =IF(Results!$M$37="Yes",'Raw Data'!W13-'Raw Data'!W$10,"") | X13: =IF(Results!$M$38="Yes",'Raw Data'!X13-'Raw Data'!X$10,"") | Y13: =IF(Results!$M$39="Yes",'Raw Data'!Y13-'Raw Data'!Y$10,"") | Z13: =IF(Results!$M$40="Yes",'Raw Data'!Z13-'Raw Data'!Z$10,"") | AA13: =IF(Results!$M$41="Yes",'Raw Data'!AA13-'Raw Data'!AA$10,"") | AB13: =IF(Results!$M$42="Yes",'Raw Data'!AB13-'Raw Data'!AB$10,"") | AC13: =IF(Results!$M$43="Yes",'Raw Data'!AC13-'Raw Data'!AC$10,"") | AD13: =IF(Results!$M$44="Yes",'Raw Data'!AD13-'Raw Data'!AD$10,"") | AE13: =IF(Results!$M$45="Yes",'Raw Data'!AE13-'Raw Data'!AE$10,"") | AF13: =IF(Results!$M$46="Yes",'Raw Data'!AF13-'Raw Data'!AF$10,"") | AG13: =IF(Results!$M$47="Yes",'Raw Data'!AG13-'Raw Data'!AG$10,"") | AH13: =IF(Results!$M$48="Yes",'Raw Data'!AH13-'Raw Data'!AH$10,"") | AI13: =IF(Results!$M$49="Yes",'Raw Data'!AI13-'Raw Data'!AI$10,"") | AJ13: =IF(Results!$M$50="Yes",'Raw Data'!AJ13-'Raw Data'!AJ$10,"") | AK13: =IF(Results!$M$51="Yes",'Raw Data'!AK13-'Raw Data'!AK$10,"") | AL13: =IF(Results!$M$52="Yes",'Raw Data'!AL13-'Raw Data'!AL$10,"") | AM13: =IF(Results!$M$53="Yes",'Raw Data'!AM13-'Raw Data'!AM$10,"") | AN13: =IF(Results!$M$54="Yes",'Raw Data'!AN13-'Raw Data'!AN$10,"") | AO13: =IF(Results!$M$55="Yes",'Raw Data'!AO13-'Raw Data'!AO$10,"") | AP13: =IF(Results!$M$56="Yes",'Raw Data'!AP13-'Raw Data'!AP$10,"")
B14: 5 | C14: =IF(Results!$M$17="Yes",'Raw Data'!C14-'Raw Data'!C$10,"") | D14: =IF(Results!$M$18="Yes",'Raw Data'!D14-'Raw Data'!D$10,"") | E14: =IF(Results!$M$19="Yes",'Raw Data'!E14-'Raw Data'!E$10,"") | F14: =IF(Results!$M$20="Yes",'Raw Data'!F14-'Raw Data'!F$10,"") | G14: =IF(Results!$M$21="Yes",'Raw Data'!G14-'Raw Data'!G$10,"") | H14: =IF(Results!$M$22="Yes",'Raw Data'!H14-'Raw Data'!H$10,"") | I14: =IF(Results!$M$23="Yes",'Raw Data'!I14-'Raw Data'!I$10,"") | J14: =IF(Results!$M$24="Yes",'Raw Data'!J14-'Raw Data'!J$10,"") | K14: =IF(Results!$M$25="Yes",'Raw Data'!K14-'Raw Data'!K$10,"") | L14: =IF(Results!$M$26="Yes",'Raw Data'!L14-'Raw Data'!L$10,"") | M14: =IF(Results!$M$27="Yes",'Raw Data'!M14-'Raw Data'!M$10,"") | N14: =IF(Results!$M$28="Yes",'Raw Data'!N14-'Raw Data'!N$10,"") | O14: =IF(Results!$M$29="Yes",'Raw Data'!O14-'Raw Data'!O$10,"") | P14: =IF(Results!$M$30="Yes",'Raw Data'!P14-'Raw Data'!P$10,"") | Q14: =IF(Results!$M$31="Yes",'Raw Data'!Q14-'Raw Data'!Q$10,"") | R14: =IF(Results!$M$32="Yes",'Raw Data'!R14-'Raw Data'!R$10,"") | S14: =IF(Results!$M$33="Yes",'Raw Data'!S14-'Raw Data'!S$10,"") | T14: =IF(Results!$M$34="Yes",'Raw Data'!T14-'Raw Data'!T$10,"") | U14: =IF(Results!$M$35="Yes",'Raw Data'!U14-'Raw Data'!U$10,"") | V14: =IF(Results!$M$36="Yes",'Raw Data'!V14-'Raw Data'!V$10,"") | W14: =IF(Results!$M$37="Yes",'Raw Data'!W14-'Raw Data'!W$10,"") | X14: =IF(Results!$M$38="Yes",'Raw Data'!X14-'Raw Data'!X$10,"") | Y14: =IF(Results!$M$39="Yes",'Raw Data'!Y14-'Raw Data'!Y$10,"") | Z14: =IF(Results!$M$40="Yes",'Raw Data'!Z14-'Raw Data'!Z$10,"") | AA14: =IF(Results!$M$41="Yes",'Raw Data'!AA14-'Raw Data'!AA$10,"") | AB14: =IF(Results!$M$42="Yes",'Raw Data'!AB14-'Raw Data'!AB$10,"") | AC14: =IF(Results!$M$43="Yes",'Raw Data'!AC14-'Raw Data'!AC$10,"") | AD14: =IF(Results!$M$44="Yes",'Raw Data'!AD14-'Raw Data'!AD$10,"") | AE14: =IF(Results!$M$45="Yes",'Raw Data'!AE14-'Raw Data'!AE$10,"") | AF14: =IF(Results!$M$46="Yes",'Raw Data'!AF14-'Raw Data'!AF$10,"") | AG14: =IF(Results!$M$47="Yes",'Raw Data'!AG14-'Raw Data'!AG$10,"") | AH14: =IF(Results!$M$48="Yes",'Raw Data'!AH14-'Raw Data'!AH$10,"") | AI14: =IF(Results!$M$49="Yes",'Raw Data'!AI14-'Raw Data'!AI$10,"") | AJ14: =IF(Results!$M$50="Yes",'Raw Data'!AJ14-'Raw Data'!AJ$10,"") | AK14: =IF(Results!$M$51="Yes",'Raw Data'!AK14-'Raw Data'!AK$10,"") | AL14: =IF(Results!$M$52="Yes",'Raw Data'!AL14-'Raw Data'!AL$10,"") | AM14: =IF(Results!$M$53="Yes",'Raw Data'!AM14-'Raw Data'!AM$10,"") | AN14: =IF(Results!$M$54="Yes",'Raw Data'!AN14-'Raw Data'!AN$10,"") | AO14: =IF(Results!$M$55="Yes",'Raw Data'!AO14-'Raw Data'!AO$10,"") | AP14: =IF(Results!$M$56="Yes",'Raw Data'!AP14-'Raw Data'!AP$10,"")
B15: 6 | C15: =IF(Results!$M$17="Yes",'Raw Data'!C15-'Raw Data'!C$10,"") | D15: =IF(Results!$M$18="Yes",'Raw Data'!D15-'Raw Data'!D$10,"") | E15: =IF(Results!$M$19="Yes",'Raw Data'!E15-'Raw Data'!E$10,"") | F15: =IF(Results!$M$20="Yes",'Raw Data'!F15-'Raw Data'!F$10,"") | G15: =IF(Results!$M$21="Yes",'Raw Data'!G15-'Raw Data'!G$10,"") | H15: =IF(Results!$M$22="Yes",'Raw Data'!H15-'Raw Data'!H$10,"") | I15: =IF(Results!$M$23="Yes",'Raw Data'!I15-'Raw Data'!I$10,"") | J15: =IF(Results!$M$24="Yes",'Raw Data'!J15-'Raw Data'!J$10,"") | K15: =IF(Results!$M$25="Yes",'Raw Data'!K15-'Raw Data'!K$10,"") | L15: =IF(Results!$M$26="Yes",'Raw Data'!L15-'Raw Data'!L$10,"") | M15: =IF(Results!$M$27="Yes",'Raw Data'!M15-'Raw Data'!M$10,"") | N15: =IF(Results!$M$28="Yes",'Raw Data'!N15-'Raw Data'!N$10,"") | O15: =IF(Results!$M$29="Yes",'Raw Data'!O15-'Raw Data'!O$10,"") | P15: =IF(Results!$M$30="Yes",'Raw Data'!P15-'Raw Data'!P$10,"") | Q15: =IF(Results!$M$31="Yes",'Raw Data'!Q15-'Raw Data'!Q$10,"") | R15: =IF(Results!$M$32="Yes",'Raw Data'!R15-'Raw Data'!R$10,"") | S15: =IF(Results!$M$33="Yes",'Raw Data'!S15-'Raw Data'!S$10,"") | T15: =IF(Results!$M$34="Yes",'Raw Data'!T15-'Raw Data'!T$10,"") | U15: =IF(Results!$M$35="Yes",'Raw Data'!U15-'Raw Data'!U$10,"") | V15: =IF(Results!$M$36="Yes",'Raw Data'!V15-'Raw Data'!V$10,"") | W15: =IF(Results!$M$37="Yes",'Raw Data'!W15-'Raw Data'!W$10,"") | X15: =IF(Results!$M$38="Yes",'Raw Data'!X15-'Raw Data'!X$10,"") | Y15: =IF(Results!$M$39="Yes",'Raw Data'!Y15-'Raw Data'!Y$10,"") | Z15: =IF(Results!$M$40="Yes",'Raw Data'!Z15-'Raw Data'!Z$10,"") | AA15: =IF(Results!$M$41="Yes",'Raw Data'!AA15-'Raw Data'!AA$10,"") | AB15: =IF(Results!$M$42="Yes",'Raw Data'!AB15-'Raw Data'!AB$10,"") | AC15: =IF(Results!$M$43="Yes",'Raw Data'!AC15-'Raw Data'!AC$10,"") | AD15: =IF(Results!$M$44="Yes",'Raw Data'!AD15-'Raw Data'!AD$10,"") | AE15: =IF(Results!$M$45="Yes",'Raw Data'!AE15-'Raw Data'!AE$10,"") | AF15: =IF(Results!$M$46="Yes",'Raw Data'!AF15-'Raw Data'!AF$10,"") | AG15: =IF(Results!$M$47="Yes",'Raw Data'!AG15-'Raw Data'!AG$10,"") | AH15: =IF(Results!$M$48="Yes",'Raw Data'!AH15-'Raw Data'!AH$10,"") | AI15: =IF(Results!$M$49="Yes",'Raw Data'!AI15-'Raw Data'!AI$10,"") | AJ15: =IF(Results!$M$50="Yes",'Raw Data'!AJ15-'Raw Data'!AJ$10,"") | AK15: =IF(Results!$M$51="Yes",'Raw Data'!AK15-'Raw Data'!AK$10,"") | AL15: =IF(Results!$M$52="Yes",'Raw Data'!AL15-'Raw Data'!AL$10,"") | AM15: =IF(Results!$M$53="Yes",'Raw Data'!AM15-'Raw Data'!AM$10,"") | AN15: =IF(Results!$M$54="Yes",'Raw Data'!AN15-'Raw Data'!AN$10,"") | AO15: =IF(Results!$M$55="Yes",'Raw Data'!AO15-'Raw Data'!AO$10,"") | AP15: =IF(Results!$M$56="Yes",'Raw Data'!AP15-'Raw Data'!AP$10,"")
B16: 7 | C16: =IF(Results!$M$17="Yes",'Raw Data'!C16-'Raw Data'!C$10,"") | D16: =IF(Results!$M$18="Yes",'Raw Data'!D16-'Raw Data'!D$10,"") | E16: =IF(Results!$M$19="Yes",'Raw Data'!E16-'Raw Data'!E$10,"") | F16: =IF(Results!$M$20="Yes",'Raw Data'!F16-'Raw Data'!F$10,"") | G16: =IF(Results!$M$21="Yes",'Raw Data'!G16-'Raw Data'!G$10,"") | H16: =IF(Results!$M$22="Yes",'Raw Data'!H16-'Raw Data'!H$10,"") | I16: =IF(Results!$M$23="Yes",'Raw Data'!I16-'Raw Data'!I$10,"") | J16: =IF(Results!$M$24="Yes",'Raw Data'!J16-'Raw Data'!J$10,"") | K16: =IF(Results!$M$25="Yes",'Raw Data'!K16-'Raw Data'!K$10,"") | L16: =IF(Results!$M$26="Yes",'Raw Data'!L16-'Raw Data'!L$10,"") | M16: =IF(Results!$M$27="Yes",'Raw Data'!M16-'Raw Data'!M$10,"") | N16: =IF(Results!$M$28="Yes",'Raw Data'!N16-'Raw Data'!N$10,"") | O16: =IF(Results!$M$29="Yes",'Raw Data'!O16-'Raw Data'!O$10,"") | P16: =IF(Results!$M$30="Yes",'Raw Data'!P16-'Raw Data'!P$10,"") | Q16: =IF(Results!$M$31="Yes",'Raw Data'!Q16-'Raw Data'!Q$10,"") | R16: =IF(Results!$M$32="Yes",'Raw Data'!R16-'Raw Data'!R$10,"") | S16: =IF(Results!$M$33="Yes",'Raw Data'!S16-'Raw Data'!S$10,"") | T16: =IF(Results!$M$34="Yes",'Raw Data'!T16-'Raw Data'!T$10,"") | U16: =IF(Results!$M$35="Yes",'Raw Data'!U16-'Raw Data'!U$10,"") | V16: =IF(Results!$M$36="Yes",'Raw Data'!V16-'Raw Data'!V$10,"") | W16: =IF(Results!$M$37="Yes",'Raw Data'!W16-'Raw Data'!W$10,"") | X16: =IF(Results!$M$38="Yes",'Raw Data'!X16-'Raw Data'!X$10,"") | Y16: =IF(Results!$M$39="Yes",'Raw Data'!Y16-'Raw Data'!Y$10,"") | Z16: =IF(Results!$M$40="Yes",'Raw Data'!Z16-'Raw Data'!Z$10,"") | AA16: =IF(Results!$M$41="Yes",'Raw Data'!AA16-'Raw Data'!AA$10,"") | AB16: =IF(Results!$M$42="Yes",'Raw Data'!AB16-'Raw Data'!AB$10,"") | AC16: =IF(Results!$M$43="Yes",'Raw Data'!AC16-'Raw Data'!AC$10,"") | AD16: =IF(Results!$M$44="Yes",'Raw Data'!AD16-'Raw Data'!AD$10,"") | AE16: =IF(Results!$M$45="Yes",'Raw Data'!AE16-'Raw Data'!AE$10,"") | AF16: =IF(Results!$M$46="Yes",'Raw Data'!AF16-'Raw Data'!AF$10,"") | AG16: =IF(Results!$M$47="Yes",'Raw Data'!AG16-'Raw Data'!AG$10,"") | AH16: =IF(Results!$M$48="Yes",'Raw Data'!AH16-'Raw Data'!AH$10,"") | AI16: =IF(Results!$M$49="Yes",'Raw Data'!AI16-'Raw Data'!AI$10,"") | AJ16: =IF(Results!$M$50="Yes",'Raw Data'!AJ16-'Raw Data'!AJ$10,"") | AK16: =IF(Results!$M$51="Yes",'Raw Data'!AK16-'Raw Data'!AK$10,"") | AL16: =IF(Results!$M$52="Yes",'Raw Data'!AL16-'Raw Data'!AL$10,"") | AM16: =IF(Results!$M$53="Yes",'Raw Data'!AM16-'Raw Data'!AM$10,"") | AN16: =IF(Results!$M$54="Yes",'Raw Data'!AN16-'Raw Data'!AN$10,"") | AO16: =IF(Results!$M$55="Yes",'Raw Data'!AO16-'Raw Data'!AO$10,"") | AP16: =IF(Results!$M$56="Yes",'Raw Data'!AP16-'Raw Data'!AP$10,"")
B17: 8 | C17: =IF(Results!$M$17="Yes",'Raw Data'!C17-'Raw Data'!C$10,"") | D17: =IF(Results!$M$18="Yes",'Raw Data'!D17-'Raw Data'!D$10,"") | E17: =IF(Results!$M$19="Yes",'Raw Data'!E17-'Raw Data'!E$10,"") | F17: =IF(Results!$M$20="Yes",'Raw Data'!F17-'Raw Data'!F$10,"") | G17: =IF(Results!$M$21="Yes",'Raw Data'!G17-'Raw Data'!G$10,"") | H17: =IF(Results!$M$22="Yes",'Raw Data'!H17-'Raw Data'!H$10,"") | I17: =IF(Results!$M$23="Yes",'Raw Data'!I17-'Raw Data'!I$10,"") | J17: =IF(Results!$M$24="Yes",'Raw Data'!J17-'Raw Data'!J$10,"") | K17: =IF(Results!$M$25="Yes",'Raw Data'!K17-'Raw Data'!K$10,"") | L17: =IF(Results!$M$26="Yes",'Raw Data'!L17-'Raw Data'!L$10,"") | M17: =IF(Results!$M$27="Yes",'Raw Data'!M17-'Raw Data'!M$10,"") | N17: =IF(Results!$M$28="Yes",'Raw Data'!N17-'Raw Data'!N$10,"") | O17: =IF(Results!$M$29="Yes",'Raw Data'!O17-'Raw Data'!O$10,"") | P17: =IF(Results!$M$30="Yes",'Raw Data'!P17-'Raw Data'!P$10,"") | Q17: =IF(Results!$M$31="Yes",'Raw Data'!Q17-'Raw Data'!Q$10,"") | R17: =IF(Results!$M$32="Yes",'Raw Data'!R17-'Raw Data'!R$10,"") | S17: =IF(Results!$M$33="Yes",'Raw Data'!S17-'Raw Data'!S$10,"") | T17: =IF(Results!$M$34="Yes",'Raw Data'!T17-'Raw Data'!T$10,"") | U17: =IF(Results!$M$35="Yes",'Raw Data'!U17-'Raw Data'!U$10,"") | V17: =IF(Results!$M$36="Yes",'Raw Data'!V17-'Raw Data'!V$10,"") | W17: =IF(Results!$M$37="Yes",'Raw Data'!W17-'Raw Data'!W$10,"") | X17: =IF(Results!$M$38="Yes",'Raw Data'!X17-'Raw Data'!X$10,"") | Y17: =IF(Results!$M$39="Yes",'Raw Data'!Y17-'Raw Data'!Y$10,"") | Z17: =IF(Results!$M$40="Yes",'Raw Data'!Z17-'Raw Data'!Z$10,"") | AA17: =IF(Results!$M$41="Yes",'Raw Data'!AA17-'Raw Data'!AA$10,"") | AB17: =IF(Results!$M$42="Yes",'Raw Data'!AB17-'Raw Data'!AB$10,"") | AC17: =IF(Results!$M$43="Yes",'Raw Data'!AC17-'Raw Data'!AC$10,"") | AD17: =IF(Results!$M$44="Yes",'Raw Data'!AD17-'Raw Data'!AD$10,"") | AE17: =IF(Results!$M$45="Yes",'Raw Data'!AE17-'Raw Data'!AE$10,"") | AF17: =IF(Results!$M$46="Yes",'Raw Data'!AF17-'Raw Data'!AF$10,"") | AG17: =IF(Results!$M$47="Yes",'Raw Data'!AG17-'Raw Data'!AG$10,"") | AH17: =IF(Results!$M$48="Yes",'Raw Data'!AH17-'Raw Data'!AH$10,"") | AI17: =IF(Results!$M$49="Yes",'Raw Data'!AI17-'Raw Data'!AI$10,"") | AJ17: =IF(Results!$M$50="Yes",'Raw Data'!AJ17-'Raw Data'!AJ$10,"") | AK17: =IF(Results!$M$51="Yes",'Raw Data'!AK17-'Raw Data'!AK$10,"") | AL17: =IF(Results!$M$52="Yes",'Raw Data'!AL17-'Raw Data'!AL$10,"") | AM17: =IF(Results!$M$53="Yes",'Raw Data'!AM17-'Raw Data'!AM$10,"") | AN17: =IF(Results!$M$54="Yes",'Raw Data'!AN17-'Raw Data'!AN$10,"") | AO17: =IF(Results!$M$55="Yes",'Raw Data'!AO17-'Raw Data'!AO$10,"") | AP17: =IF(Results!$M$56="Yes",'Raw Data'!AP17-'Raw Data'!AP$10,"")
B18: 9 | C18: =IF(Results!$M$17="Yes",'Raw Data'!C18-'Raw Data'!C$10,"") | D18: =IF(Results!$M$18="Yes",'Raw Data'!D18-'Raw Data'!D$10,"") | E18: =IF(Results!$M$19="Yes",'Raw Data'!E18-'Raw Data'!E$10,"") | F18: =IF(Results!$M$20="Yes",'Raw Data'!F18-'Raw Data'!F$10,"") | G18: =IF(Results!$M$21="Yes",'Raw Data'!G18-'Raw Data'!G$10,"") | H18: =IF(Results!$M$22="Yes",'Raw Data'!H18-'Raw Data'!H$10,"") | I18: =IF(Results!$M$23="Yes",'Raw Data'!I18-'Raw Data'!I$10,"") | J18: =IF(Results!$M$24="Yes",'Raw Data'!J18-'Raw Data'!J$10,"") | K18: =IF(Results!$M$25="Yes",'Raw Data'!K18-'Raw Data'!K$10,"") | L18: =IF(Results!$M$26="Yes",'Raw Data'!L18-'Raw Data'!L$10,"") | M18: =IF(Results!$M$27="Yes",'Raw Data'!M18-'Raw Data'!M$10,"") | N18: =IF(Results!$M$28="Yes",'Raw Data'!N18-'Raw Data'!N$10,"") | O18: =IF(Results!$M$29="Yes",'Raw Data'!O18-'Raw Data'!O$10,"") | P18: =IF(Results!$M$30="Yes",'Raw Data'!P18-'Raw Data'!P$10,"") | Q18: =IF(Results!$M$31="Yes",'Raw Data'!Q18-'Raw Data'!Q$10,"") | R18: =IF(Results!$M$32="Yes",'Raw Data'!R18-'Raw Data'!R$10,"") | S18: =IF(Results!$M$33="Yes",'Raw Data'!S18-'Raw Data'!S$10,"") | T18: =IF(Results!$M$34="Yes",'Raw Data'!T18-'Raw Data'!T$10,"") | U18: =IF(Results!$M$35="Yes",'Raw Data'!U18-'Raw Data'!U$10,"") | V18: =IF(Results!$M$36="Yes",'Raw Data'!V18-'Raw Data'!V$10,"") | W18: =IF(Results!$M$37="Yes",'Raw Data'!W18-'Raw Data'!W$10,"") | X18: =IF(Results!$M$38="Yes",'Raw Data'!X18-'Raw Data'!X$10,"") | Y18: =IF(Results!$M$39="Yes",'Raw Data'!Y18-'Raw Data'!Y$10,"") | Z18: =IF(Results!$M$40="Yes",'Raw Data'!Z18-'Raw Data'!Z$10,"") | AA18: =IF(Results!$M$41="Yes",'Raw Data'!AA18-'Raw Data'!AA$10,"") | AB18: =IF(Results!$M$42="Yes",'Raw Data'!AB18-'Raw Data'!AB$10,"") | AC18: =IF(Results!$M$43="Yes",'Raw Data'!AC18-'Raw Data'!AC$10,"") | AD18: =IF(Results!$M$44="Yes",'Raw Data'!AD18-'Raw Data'!AD$10,"") | AE18: =IF(Results!$M$45="Yes",'Raw Data'!AE18-'Raw Data'!AE$10,"") | AF18: =IF(Results!$M$46="Yes",'Raw Data'!AF18-'Raw Data'!AF$10,"") | AG18: =IF(Results!$M$47="Yes",'Raw Data'!AG18-'Raw Data'!AG$10,"") | AH18: =IF(Results!$M$48="Yes",'Raw Data'!AH18-'Raw Data'!AH$10,"") | AI18: =IF(Results!$M$49="Yes",'Raw Data'!AI18-'Raw Data'!AI$10,"") | AJ18: =IF(Results!$M$50="Yes",'Raw Data'!AJ18-'Raw Data'!AJ$10,"") | AK18: =IF(Results!$M$51="Yes",'Raw Data'!AK18-'Raw Data'!AK$10,"") | AL18: =IF(Results!$M$52="Yes",'Raw Data'!AL18-'Raw Data'!AL$10,"") | AM18: =IF(Results!$M$53="Yes",'Raw Data'!AM18-'Raw Data'!AM$10,"") | AN18: =IF(Results!$M$54="Yes",'Raw Data'!AN18-'Raw Data'!AN$10,"") | AO18: =IF(Results!$M$55="Yes",'Raw Data'!AO18-'Raw Data'!AO$10,"") | AP18: =IF(Results!$M$56="Yes",'Raw Data'!AP18-'Raw Data'!AP$10,"")
B19: 10 | C19: =IF(Results!$M$17="Yes",'Raw Data'!C19-'Raw Data'!C$10,"") | D19: =IF(Results!$M$18="Yes",'Raw Data'!D19-'Raw Data'!D$10,"") | E19: =IF(Results!$M$19="Yes",'Raw Data'!E19-'Raw Data'!E$10,"") | F19: =IF(Results!$M$20="Yes",'Raw Data'!F19-'Raw Data'!F$10,"") | G19: =IF(Results!$M$21="Yes",'Raw Data'!G19-'Raw Data'!G$10,"") | H19: =IF(Results!$M$22="Yes",'Raw Data'!H19-'Raw Data'!H$10,"") | I19: =IF(Results!$M$23="Yes",'Raw Data'!I19-'Raw Data'!I$10,"") | J19: =IF(Results!$M$24="Yes",'Raw Data'!J19-'Raw Data'!J$10,"") | K19: =IF(Results!$M$25="Yes",'Raw Data'!K19-'Raw Data'!K$10,"") | L19: =IF(Results!$M$26="Yes",'Raw Data'!L19-'Raw Data'!L$10,"") | M19: =IF(Results!$M$27="Yes",'Raw Data'!M19-'Raw Data'!M$10,"") | N19: =IF(Results!$M$28="Yes",'Raw Data'!N19-'Raw Data'!N$10,"") | O19: =IF(Results!$M$29="Yes",'Raw Data'!O19-'Raw Data'!O$10,"") | P19: =IF(Results!$M$30="Yes",'Raw Data'!P19-'Raw Data'!P$10,"") | Q19: =IF(Results!$M$31="Yes",'Raw Data'!Q19-'Raw Data'!Q$10,"") | R19: =IF(Results!$M$32="Yes",'Raw Data'!R19-'Raw Data'!R$10,"") | S19: =IF(Results!$M$33="Yes",'Raw Data'!S19-'Raw Data'!S$10,"") | T19: =IF(Results!$M$34="Yes",'Raw Data'!T19-'Raw Data'!T$10,"") | U19: =IF(Results!$M$35="Yes",'Raw Data'!U19-'Raw Data'!U$10,"") | V19: =IF(Results!$M$36="Yes",'Raw Data'!V19-'Raw Data'!V$10,"") | W19: =IF(Results!$M$37="Yes",'Raw Data'!W19-'Raw Data'!W$10,"") | X19: =IF(Results!$M$38="Yes",'Raw Data'!X19-'Raw Data'!X$10,"") | Y19: =IF(Results!$M$39="Yes",'Raw Data'!Y19-'Raw Data'!Y$10,"") | Z19: =IF(Results!$M$40="Yes",'Raw Data'!Z19-'Raw Data'!Z$10,"") | AA19: =IF(Results!$M$41="Yes",'Raw Data'!AA19-'Raw Data'!AA$10,"") | AB19: =IF(Results!$M$42="Yes",'Raw Data'!AB19-'Raw Data'!AB$10,"") | AC19: =IF(Results!$M$43="Yes",'Raw Data'!AC19-'Raw Data'!AC$10,"") | AD19: =IF(Results!$M$44="Yes",'Raw Data'!AD19-'Raw Data'!AD$10,"") | AE19: =IF(Results!$M$45="Yes",'Raw Data'!AE19-'Raw Data'!AE$10,"") | AF19: =IF(Results!$M$46="Yes",'Raw Data'!AF19-'Raw Data'!AF$10,"") | AG19: =IF(Results!$M$47="Yes",'Raw Data'!AG19-'Raw Data'!AG$10,"") | AH19: =IF(Results!$M$48="Yes",'Raw Data'!AH19-'Raw Data'!AH$10,"") | AI19: =IF(Results!$M$49="Yes",'Raw Data'!AI19-'Raw Data'!AI$10,"") | AJ19: =IF(Results!$M$50="Yes",'Raw Data'!AJ19-'Raw Data'!AJ$10,"") | AK19: =IF(Results!$M$51="Yes",'Raw Data'!AK19-'Raw Data'!AK$10,"") | AL19: =IF(Results!$M$52="Yes",'Raw Data'!AL19-'Raw Data'!AL$10,"") | AM19: =IF(Results!$M$53="Yes",'Raw Data'!AM19-'Raw Data'!AM$10,"") | AN19: =IF(Results!$M$54="Yes",'Raw Data'!AN19-'Raw Data'!AN$10,"") | AO19: =IF(Results!$M$55="Yes",'Raw Data'!AO19-'Raw Data'!AO$10,"") | AP19: =IF(Results!$M$56="Yes",'Raw Data'!AP19-'Raw Data'!AP$10,"")
B20: 11 | C20: =IF(Results!$M$17="Yes",'Raw Data'!C20-'Raw Data'!C$10,"") | D20: =IF(Results!$M$18="Yes",'Raw Data'!D20-'Raw Data'!D$10,"") | E20: =IF(Results!$M$19="Yes",'Raw Data'!E20-'Raw Data'!E$10,"") | F20: =IF(Results!$M$20="Yes",'Raw Data'!F20-'Raw Data'!F$10,"") | G20: =IF(Results!$M$21="Yes",'Raw Data'!G20-'Raw Data'!G$10,"") | H20: =IF(Results!$M$22="Yes",'Raw Data'!H20-'Raw Data'!H$10,"") | I20: =IF(Results!$M$23="Yes",'Raw Data'!I20-'Raw Data'!I$10,"") | J20: =IF(Results!$M$24="Yes",'Raw Data'!J20-'Raw Data'!J$10,"") | K20: =IF(Results!$M$25="Yes",'Raw Data'!K20-'Raw Data'!K$10,"") | L20: =IF(Results!$M$26="Yes",'Raw Data'!L20-'Raw Data'!L$10,"") | M20: =IF(Results!$M$27="Yes",'Raw Data'!M20-'Raw Data'!M$10,"") | N20: =IF(Results!$M$28="Yes",'Raw Data'!N20-'Raw Data'!N$10,"") | O20: =IF(Results!$M$29="Yes",'Raw Data'!O20-'Raw Data'!O$10,"") | P20: =IF(Results!$M$30="Yes",'Raw Data'!P20-'Raw Data'!P$10,"") | Q20: =IF(Results!$M$31="Yes",'Raw Data'!Q20-'Raw Data'!Q$10,"") | R20: =IF(Results!$M$32="Yes",'Raw Data'!R20-'Raw Data'!R$10,"") | S20: =IF(Results!$M$33="Yes",'Raw Data'!S20-'Raw Data'!S$10,"") | T20: =IF(Results!$M$34="Yes",'Raw Data'!T20-'Raw Data'!T$10,"") | U20: =IF(Results!$M$35="Yes",'Raw Data'!U20-'Raw Data'!U$10,"") | V20: =IF(Results!$M$36="Yes",'Raw Data'!V20-'Raw Data'!V$10,"") | W20: =IF(Results!$M$37="Yes",'Raw Data'!W20-'Raw Data'!W$10,"") | X20: =IF(Results!$M$38="Yes",'Raw Data'!X20-'Raw Data'!X$10,"") | Y20: =IF(Results!$M$39="Yes",'Raw Data'!Y20-'Raw Data'!Y$10,"") | Z20: =IF(Results!$M$40="Yes",'Raw Data'!Z20-'Raw Data'!Z$10,"") | AA20: =IF(Results!$M$41="Yes",'Raw Data'!AA20-'Raw Data'!AA$10,"") | AB20: =IF(Results!$M$42="Yes",'Raw Data'!AB20-'Raw Data'!AB$10,"") | AC20: =IF(Results!$M$43="Yes",'Raw Data'!AC20-'Raw Data'!AC$10,"") | AD20: =IF(Results!$M$44="Yes",'Raw Data'!AD20-'Raw Data'!AD$10,"") | AE20: =IF(Results!$M$45="Yes",'Raw Data'!AE20-'Raw Data'!AE$10,"") | AF20: =IF(Results!$M$46="Yes",'Raw Data'!AF20-'Raw Data'!AF$10,"") | AG20: =IF(Results!$M$47="Yes",'Raw Data'!AG20-'Raw Data'!AG$10,"") | AH20: =IF(Results!$M$48="Yes",'Raw Data'!AH20-'Raw Data'!AH$10,"") | AI20: =IF(Results!$M$49="Yes",'Raw Data'!AI20-'Raw Data'!AI$10,"") | AJ20: =IF(Results!$M$50="Yes",'Raw Data'!AJ20-'Raw Data'!AJ$10,"") | AK20: =IF(Results!$M$51="Yes",'Raw Data'!AK20-'Raw Data'!AK$10,"") | AL20: =IF(Results!$M$52="Yes",'Raw Data'!AL20-'Raw Data'!AL$10,"") | AM20: =IF(Results!$M$53="Yes",'Raw Data'!AM20-'Raw Data'!AM$10,"") | AN20: =IF(Results!$M$54="Yes",'Raw Data'!AN20-'Raw Data'!AN$10,"") | AO20: =IF(Results!$M$55="Yes",'Raw Data'!AO20-'Raw Data'!AO$10,"") | AP20: =IF(Results!$M$56="Yes",'Raw Data'!AP20-'Raw Data'!AP$10,"")
